2025-01-27 19:18:47,485 FILE: database.py IN: create_database MESSAGE: DATABASE: ¡‡Á˚ ‰‡ÌÌ˚ı ÒÓÁ‰‡Ì˚
2025-01-27 19:19:18,661 FILE: database.py IN: create_database MESSAGE: DATABASE: ¡‡Á˚ ‰‡ÌÌ˚ı ÒÓÁ‰‡Ì˚
2025-01-27 19:20:54,991 FILE: database.py IN: create_database MESSAGE: DATABASE: ¡‡Á˚ ‰‡ÌÌ˚ı ÒÓÁ‰‡Ì˚
2025-01-30 17 - root - INFO - DATABASE: INSERT INTO messages VALUES (5948417394, –ø—Ä–∏–≤–µ—Ç, user, 0)
2025-01-30 17 - TeleBot - ERROR - Infinity polling exception: list index out of range
2025-01-30 17 - TeleBot - ERROR - Exception traceback:
Traceback (most recent call last):
  File "C:\Users\–¢–∏–º–∞\PycharmProjects\TelegramBot\venv\Lib\site-packages\telebot\__init__.py", line 1110, in infinity_polling
    self.polling(non_stop=True, timeout=timeout, long_polling_timeout=long_polling_timeout,
    ~~~~~~~~~~~~^^^^^^^^^^^^^^^^^^^^^^^^^^^^^^^^^^^^^^^^^^^^^^^^^^^^^^^^^^^^^^^^^^^^^^^^^^^
                 logger_level=logger_level, allowed_updates=allowed_updates, restart_on_change=False,
                 ^^^^^^^^^^^^^^^^^^^^^^^^^^^^^^^^^^^^^^^^^^^^^^^^^^^^^^^^^^^^^^^^^^^^^^^^^^^^^^^^^^^^
                 *args, **kwargs)
                 ^^^^^^^^^^^^^^^^
  File "C:\Users\–¢–∏–º–∞\PycharmProjects\TelegramBot\venv\Lib\site-packages\telebot\__init__.py", line 1198, in polling
    self.__threaded_polling(non_stop=non_stop, interval=interval, timeout=timeout, long_polling_timeout=long_polling_timeout,
    ~~~~~~~~~~~~~~~~~~~~~~~^^^^^^^^^^^^^^^^^^^^^^^^^^^^^^^^^^^^^^^^^^^^^^^^^^^^^^^^^^^^^^^^^^^^^^^^^^^^^^^^^^^^^^^^^^^^^^^^^^
                            logger_level=logger_level, allowed_updates=allowed_updates)
                            ^^^^^^^^^^^^^^^^^^^^^^^^^^^^^^^^^^^^^^^^^^^^^^^^^^^^^^^^^^^
  File "C:\Users\–¢–∏–º–∞\PycharmProjects\TelegramBot\venv\Lib\site-packages\telebot\__init__.py", line 1273, in __threaded_polling
    raise e
  File "C:\Users\–¢–∏–º–∞\PycharmProjects\TelegramBot\venv\Lib\site-packages\telebot\__init__.py", line 1235, in __threaded_polling
    self.worker_pool.raise_exceptions()
    ~~~~~~~~~~~~~~~~~~~~~~~~~~~~~~~~~^^
  File "C:\Users\–¢–∏–º–∞\PycharmProjects\TelegramBot\venv\Lib\site-packages\telebot\util.py", line 150, in raise_exceptions
    raise self.exception_info
  File "C:\Users\–¢–∏–º–∞\PycharmProjects\TelegramBot\venv\Lib\site-packages\telebot\util.py", line 93, in run
    task(*args, **kwargs)
    ~~~~^^^^^^^^^^^^^^^^^
  File "C:\Users\–¢–∏–º–∞\PycharmProjects\TelegramBot\venv\Lib\site-packages\telebot\__init__.py", line 9233, in _run_middlewares_and_handler
    result = handler['function'](message)
  File "C:\Users\–¢–∏–º–∞\PycharmProjects\TelegramBot\main.py", line 56, in handle_text
    status, answer, answer_tokens = ask_gpt(chat_history[user_id])
                                            ~~~~~~~~~~~~^^^^^^^^^
IndexError: list index out of range

2025-01-30 17 - TeleBot - ERROR - Infinity polling: polling exited
2025-01-30 17 - TeleBot - ERROR - Break infinity polling
2025-01-30 17 - root - INFO - DATABASE: INSERT INTO messages VALUES (5948417394, –ø—Ä–∏–≤–µ—Ç, user, 0)
2025-01-30 17 - TeleBot - ERROR - Infinity polling: polling exited
2025-01-30 17 - TeleBot - ERROR - Break infinity polling
2025-01-30 17 - root - INFO - DATABASE: INSERT INTO messages VALUES (5948417394, –ª—è, user, 0)
2025-01-30 17 - TeleBot - ERROR - Infinity polling: polling exited
2025-01-30 17 - TeleBot - ERROR - Break infinity polling
2025-01-30 17 - root - INFO - DATABASE: INSERT INTO messages VALUES (5948417394, kz, user, 0)
2025-01-30 17 - TeleBot - ERROR - Infinity polling: polling exited
2025-01-30 17 - TeleBot - ERROR - Break infinity polling
2025-01-30 17 - root - INFO - DATABASE: INSERT INTO messages VALUES (5948417394, –î–∞—Ä–æ–≤–∞!, user, 0)
2025-01-30 17 - root - INFO - DATABASE: INSERT INTO messages VALUES (5948417394, –ü—Ä–∏–≤–µ—Ç! –ö–∞–∫ –¥–µ–ª–∞? –ß—Ç–æ –Ω–æ–≤–æ–≥–æ?, asistant, 9)
2025-01-30 17 - TeleBot - ERROR - Infinity polling: polling exited
2025-01-30 17 - TeleBot - ERROR - Break infinity polling
2025-01-30 17 - TeleBot - ERROR - Infinity polling exception: HTTPSConnectionPool(host='api.telegram.org', port=443): Max retries exceeded with url: /bot7221935484:***********************************/getUpdates?offset=1&timeout=20 (Caused by SSLError(SSLEOFError(8, '[SSL: UNEXPECTED_EOF_WHILE_READING] EOF occurred in violation of protocol (_ssl.c:1018)')))
2025-01-30 17 - TeleBot - ERROR - Exception traceback:
Traceback (most recent call last):
  File "C:\Users\–¢–∏–º–∞\PycharmProjects\TelegramBot\venv\Lib\site-packages\urllib3\connectionpool.py", line 464, in _make_request
    self._validate_conn(conn)
    ~~~~~~~~~~~~~~~~~~~^^^^^^
  File "C:\Users\–¢–∏–º–∞\PycharmProjects\TelegramBot\venv\Lib\site-packages\urllib3\connectionpool.py", line 1093, in _validate_conn
    conn.connect()
    ~~~~~~~~~~~~^^
  File "C:\Users\–¢–∏–º–∞\PycharmProjects\TelegramBot\venv\Lib\site-packages\urllib3\connection.py", line 741, in connect
    sock_and_verified = _ssl_wrap_socket_and_match_hostname(
        sock=sock,
    ...<14 lines>...
        assert_fingerprint=self.assert_fingerprint,
    )
  File "C:\Users\–¢–∏–º–∞\PycharmProjects\TelegramBot\venv\Lib\site-packages\urllib3\connection.py", line 920, in _ssl_wrap_socket_and_match_hostname
    ssl_sock = ssl_wrap_socket(
        sock=sock,
    ...<8 lines>...
        tls_in_tls=tls_in_tls,
    )
  File "C:\Users\–¢–∏–º–∞\PycharmProjects\TelegramBot\venv\Lib\site-packages\urllib3\util\ssl_.py", line 460, in ssl_wrap_socket
    ssl_sock = _ssl_wrap_socket_impl(sock, context, tls_in_tls, server_hostname)
  File "C:\Users\–¢–∏–º–∞\PycharmProjects\TelegramBot\venv\Lib\site-packages\urllib3\util\ssl_.py", line 504, in _ssl_wrap_socket_impl
    return ssl_context.wrap_socket(sock, server_hostname=server_hostname)
           ~~~~~~~~~~~~~~~~~~~~~~~^^^^^^^^^^^^^^^^^^^^^^^^^^^^^^^^^^^^^^^
  File "C:\Program Files\Python313\Lib\ssl.py", line 455, in wrap_socket
    return self.sslsocket_class._create(
           ~~~~~~~~~~~~~~~~~~~~~~~~~~~~^
        sock=sock,
        ^^^^^^^^^^
    ...<5 lines>...
        session=session
        ^^^^^^^^^^^^^^^
    )
    ^
  File "C:\Program Files\Python313\Lib\ssl.py", line 1076, in _create
    self.do_handshake()
    ~~~~~~~~~~~~~~~~~^^
  File "C:\Program Files\Python313\Lib\ssl.py", line 1372, in do_handshake
    self._sslobj.do_handshake()
    ~~~~~~~~~~~~~~~~~~~~~~~~~^^
ssl.SSLEOFError: [SSL: UNEXPECTED_EOF_WHILE_READING] EOF occurred in violation of protocol (_ssl.c:1018)

During handling of the above exception, another exception occurred:

Traceback (most recent call last):
  File "C:\Users\–¢–∏–º–∞\PycharmProjects\TelegramBot\venv\Lib\site-packages\urllib3\connectionpool.py", line 787, in urlopen
    response = self._make_request(
        conn,
    ...<10 lines>...
        **response_kw,
    )
  File "C:\Users\–¢–∏–º–∞\PycharmProjects\TelegramBot\venv\Lib\site-packages\urllib3\connectionpool.py", line 488, in _make_request
    raise new_e
urllib3.exceptions.SSLError: [SSL: UNEXPECTED_EOF_WHILE_READING] EOF occurred in violation of protocol (_ssl.c:1018)

The above exception was the direct cause of the following exception:

Traceback (most recent call last):
  File "C:\Users\–¢–∏–º–∞\PycharmProjects\TelegramBot\venv\Lib\site-packages\requests\adapters.py", line 667, in send
    resp = conn.urlopen(
        method=request.method,
    ...<9 lines>...
        chunked=chunked,
    )
  File "C:\Users\–¢–∏–º–∞\PycharmProjects\TelegramBot\venv\Lib\site-packages\urllib3\connectionpool.py", line 841, in urlopen
    retries = retries.increment(
        method, url, error=new_e, _pool=self, _stacktrace=sys.exc_info()[2]
    )
  File "C:\Users\–¢–∏–º–∞\PycharmProjects\TelegramBot\venv\Lib\site-packages\urllib3\util\retry.py", line 519, in increment
    raise MaxRetryError(_pool, url, reason) from reason  # type: ignore[arg-type]
    ^^^^^^^^^^^^^^^^^^^^^^^^^^^^^^^^^^^^^^^^^^^^^^^^^^^
urllib3.exceptions.MaxRetryError: HTTPSConnectionPool(host='api.telegram.org', port=443): Max retries exceeded with url: /bot7221935484:***********************************/getUpdates?offset=1&timeout=20 (Caused by SSLError(SSLEOFError(8, '[SSL: UNEXPECTED_EOF_WHILE_READING] EOF occurred in violation of protocol (_ssl.c:1018)')))

During handling of the above exception, another exception occurred:

Traceback (most recent call last):
  File "C:\Users\–¢–∏–º–∞\PycharmProjects\TelegramBot\venv\Lib\site-packages\telebot\__init__.py", line 1110, in infinity_polling
    self.polling(non_stop=True, timeout=timeout, long_polling_timeout=long_polling_timeout,
    ~~~~~~~~~~~~^^^^^^^^^^^^^^^^^^^^^^^^^^^^^^^^^^^^^^^^^^^^^^^^^^^^^^^^^^^^^^^^^^^^^^^^^^^
                 logger_level=logger_level, allowed_updates=allowed_updates, restart_on_change=False,
                 ^^^^^^^^^^^^^^^^^^^^^^^^^^^^^^^^^^^^^^^^^^^^^^^^^^^^^^^^^^^^^^^^^^^^^^^^^^^^^^^^^^^^
                 *args, **kwargs)
                 ^^^^^^^^^^^^^^^^
  File "C:\Users\–¢–∏–º–∞\PycharmProjects\TelegramBot\venv\Lib\site-packages\telebot\__init__.py", line 1198, in polling
    self.__threaded_polling(non_stop=non_stop, interval=interval, timeout=timeout, long_polling_timeout=long_polling_timeout,
    ~~~~~~~~~~~~~~~~~~~~~~~^^^^^^^^^^^^^^^^^^^^^^^^^^^^^^^^^^^^^^^^^^^^^^^^^^^^^^^^^^^^^^^^^^^^^^^^^^^^^^^^^^^^^^^^^^^^^^^^^^
                            logger_level=logger_level, allowed_updates=allowed_updates)
                            ^^^^^^^^^^^^^^^^^^^^^^^^^^^^^^^^^^^^^^^^^^^^^^^^^^^^^^^^^^^
  File "C:\Users\–¢–∏–º–∞\PycharmProjects\TelegramBot\venv\Lib\site-packages\telebot\__init__.py", line 1273, in __threaded_polling
    raise e
  File "C:\Users\–¢–∏–º–∞\PycharmProjects\TelegramBot\venv\Lib\site-packages\telebot\__init__.py", line 1234, in __threaded_polling
    polling_thread.raise_exceptions()
    ~~~~~~~~~~~~~~~~~~~~~~~~~~~~~~~^^
  File "C:\Users\–¢–∏–º–∞\PycharmProjects\TelegramBot\venv\Lib\site-packages\telebot\util.py", line 111, in raise_exceptions
    raise self.exception_info
  File "C:\Users\–¢–∏–º–∞\PycharmProjects\TelegramBot\venv\Lib\site-packages\telebot\util.py", line 93, in run
    task(*args, **kwargs)
    ~~~~^^^^^^^^^^^^^^^^^
  File "C:\Users\–¢–∏–º–∞\PycharmProjects\TelegramBot\venv\Lib\site-packages\telebot\__init__.py", line 688, in __retrieve_updates
    updates = self.get_updates(offset=(self.last_update_id + 1),
                               allowed_updates=allowed_updates,
                               timeout=timeout, long_polling_timeout=long_polling_timeout)
  File "C:\Users\–¢–∏–º–∞\PycharmProjects\TelegramBot\venv\Lib\site-packages\telebot\__init__.py", line 660, in get_updates
    json_updates = apihelper.get_updates(
        self.token, offset=offset, limit=limit, timeout=timeout, allowed_updates=allowed_updates,
        long_polling_timeout=long_polling_timeout)
  File "C:\Users\–¢–∏–º–∞\PycharmProjects\TelegramBot\venv\Lib\site-packages\telebot\apihelper.py", line 332, in get_updates
    return _make_request(token, method_url, params=payload)
  File "C:\Users\–¢–∏–º–∞\PycharmProjects\TelegramBot\venv\Lib\site-packages\telebot\apihelper.py", line 162, in _make_request
    result = _get_req_session().request(
        method, request_url, params=params, files=files,
        timeout=(connect_timeout, read_timeout), proxies=proxy)
  File "C:\Users\–¢–∏–º–∞\PycharmProjects\TelegramBot\venv\Lib\site-packages\requests\sessions.py", line 589, in request
    resp = self.send(prep, **send_kwargs)
  File "C:\Users\–¢–∏–º–∞\PycharmProjects\TelegramBot\venv\Lib\site-packages\requests\sessions.py", line 703, in send
    r = adapter.send(request, **kwargs)
  File "C:\Users\–¢–∏–º–∞\PycharmProjects\TelegramBot\venv\Lib\site-packages\requests\adapters.py", line 698, in send
    raise SSLError(e, request=request)
requests.exceptions.SSLError: HTTPSConnectionPool(host='api.telegram.org', port=443): Max retries exceeded with url: /bot7221935484:***********************************/getUpdates?offset=1&timeout=20 (Caused by SSLError(SSLEOFError(8, '[SSL: UNEXPECTED_EOF_WHILE_READING] EOF occurred in violation of protocol (_ssl.c:1018)')))

2025-01-30 17 - TeleBot - ERROR - Infinity polling: polling exited
2025-01-30 17 - TeleBot - ERROR - Break infinity polling
2025-01-30 17 - TeleBot - ERROR - Infinity polling: polling exited
2025-01-30 17 - TeleBot - ERROR - Break infinity polling
2025-01-30 17 - root - INFO - DATABASE: INSERT INTO messages VALUES (5948417394, –ß—Ç–æ —Ç–∞–∫–æ–µ —Å–∏–Ω—É—Å? –ö–∞–∫ –µ–≥–æ –í—ã—á–∏—Å–ª—è—Ç—å?, user, 0)
2025-01-30 17 - TeleBot - ERROR - Infinity polling: polling exited
2025-01-30 17 - TeleBot - ERROR - Break infinity polling
2025-01-30 17 - root - INFO - DATABASE: INSERT INTO messages VALUES (5948417394, –ö–∞–∫ –Ω–∞–π—Ç–∏ –∫–æ—Å–∏–Ω—É—Å?, user, 0)
2025-01-30 17 - TeleBot - ERROR - Infinity polling: polling exited
2025-01-30 17 - TeleBot - ERROR - Break infinity polling
2025-01-30 17 - root - INFO - DATABASE: INSERT INTO messages VALUES (5948417394, –ß—Ç–æ —Ç–∞–∫–æ–µ —Å–∏–Ω—É—Å? –∫–∞–∫ –µ–≥–æ –Ω–∞–π—Ç–∏?, user, 0)
2025-01-30 17 - root - INFO - DATABASE: INSERT INTO messages VALUES (5948417394, –°–∏–Ω—É—Å ‚Äî —ç—Ç–æ —Ç—Ä–∏–≥–æ–Ω–æ–º–µ—Ç—Ä–∏—á–µ—Å–∫–∞—è —Ñ—É–Ω–∫—Ü–∏—è, –∫–æ—Ç–æ—Ä–∞—è –æ–ø—Ä–µ–¥–µ–ª—è–µ—Ç –æ—Ç–Ω–æ—à–µ–Ω–∏–µ –¥–ª–∏–Ω—ã –ø—Ä–æ—Ç–∏–≤–æ–ª–µ–∂–∞—â–µ–≥–æ –∫–∞—Ç–µ—Ç–∞ (—Å—Ç–æ—Ä–æ–Ω—ã, –Ω–∞–ø—Ä–æ—Ç–∏–≤ —É–≥–ª–∞) –∫ –¥–ª–∏–Ω–µ –≥–∏–ø–æ—Ç–µ–Ω—É–∑—ã (—Å–∞–º–æ–π –¥–ª–∏–Ω–Ω–æ–π —Å—Ç–æ—Ä–æ–Ω–µ) –≤ –ø—Ä—è–º–æ—É–≥–æ–ª—å–Ω–æ–º —Ç—Ä–µ—É–≥–æ–ª—å–Ω–∏–∫–µ. –°–∏–Ω—É—Å –æ–±—ã—á–Ω–æ –æ–±–æ–∑–Ω–∞—á–∞–µ—Ç—Å—è –∫–∞–∫ sin.

–ß—Ç–æ–±—ã –Ω–∞–π—Ç–∏ —Å–∏–Ω—É—Å —É–≥–ª–∞, –≤—ã –º–æ–∂–µ—Ç–µ –∏—Å–ø–æ–ª—å–∑–æ–≤–∞—Ç—å —Å–ª–µ–¥—É—é—â—É—é —Ñ–æ—Ä–º—É–ª—É:

\[ \sin(\theta) = \frac{\text{–¥–ª–∏–Ω–∞ –ø—Ä–æ—Ç–∏–≤–æ–ª–µ–∂–∞—â–µ–≥–æ –∫–∞—Ç–µ—Ç–∞}}{\text{–¥–ª–∏–Ω–∞ –≥–∏–ø–æ—Ç–µ–Ω—É–∑—ã}} \]

–¢–∞–∫–∂–µ —Å–∏–Ω—É—Å —É–≥–ª–∞ –º–æ–∂–Ω–æ –æ–ø—Ä–µ–¥–µ–ª–∏—Ç—å, –∏—Å–ø–æ–ª—å–∑—É—è –µ–¥–∏–Ω–∏—á–Ω—É—é –æ–∫—Ä—É–∂–Ω–æ—Å—Ç—å. –ù–∞ –µ–¥–∏–Ω–∏—á–Ω–æ–π –æ–∫—Ä—É–∂–Ω–æ—Å—Ç–∏ —Å–∏–Ω—É—Å —É–≥–ª–∞ —Ä–∞–≤–µ–Ω y-–∫–æ–æ—Ä–¥–∏–Ω–∞—Ç–µ —Ç–æ—á–∫–∏, –≤ –∫–æ—Ç–æ—Ä–æ–π –ª—É—á, –æ–±—Ä–∞–∑—É—é—â–∏–π —É–≥–æ–ª Œ∏ —Å –ø–æ–ª–æ–∂–∏—Ç–µ–ª—å–Ω—ã–º –Ω–∞–ø—Ä–∞–≤–ª–µ–Ω–∏–µ–º –æ—Å–∏ X, –ø–µ—Ä–µ—Å–µ–∫–∞–µ—Ç –æ–∫—Ä—É–∂–Ω–æ—Å—Ç—å —Ä–∞–¥–∏—É—Å–æ–º 1.

–î–ª—è –≤—ã—á–∏—Å–ª–µ–Ω–∏—è —Å–∏–Ω—É—Å–∞ —É–≥–ª–∞, –≤—ã –º–æ–∂–µ—Ç–µ –∏—Å–ø–æ–ª—å–∑–æ–≤–∞—Ç—å –º–∞—Ç–µ–º–∞—Ç–∏—á–µ—Å–∫–∏–µ —Ç–∞–±–ª–∏—Ü—ã, –∫–∞–ª—å–∫—É–ª—è—Ç–æ—Ä—ã –∏–ª–∏ —Ç—Ä–∏–≥–æ–Ω–æ–º–µ—Ç—Ä–∏—á–µ—Å–∫–∏–µ —Ñ—É–Ω–∫—Ü–∏–∏ –≤ –ø—Ä–æ–≥—Ä–∞–º–º–∏—Ä–æ–≤–∞–Ω–∏–∏. –ù–∞–ø—Ä–∏–º–µ—Ä, –≤ —è–∑—ã–∫–µ Python –¥–ª—è –≤—ã—á–∏—Å–ª–µ–Ω–∏—è —Å–∏–Ω—É—Å–∞ –º–æ–∂–Ω–æ –∏—Å–ø–æ–ª—å–∑–æ–≤–∞—Ç—å —Ñ—É–Ω–∫—Ü–∏—é `math.sin()`, –∫–æ—Ç–æ—Ä–∞—è –ø—Ä–∏–Ω–∏–º–∞–µ—Ç —É–≥–æ–ª –≤ —Ä–∞–¥–∏–∞–Ω–∞—Ö., assistant, 238)
2025-01-30 17 - root - INFO - DATABASE: INSERT INTO messages VALUES (5948417394, [ \sin(\theta) = \frac{\text{–¥–ª–∏–Ω–∞ –ø—Ä–æ—Ç–∏–≤–æ–ª–µ–∂–∞—â–µ–≥–æ –∫–∞—Ç–µ—Ç–∞}}{\text{–¥–ª–∏–Ω–∞ –≥–∏–ø–æ—Ç–µ–Ω—É–∑—ã}} \] - —á—Ç–æ —ç—Ç–æ –∑–∞ —Ç–µ–∫—Å—Ç?, user, 0)
2025-01-30 17 - root - INFO - DATABASE: INSERT INTO messages VALUES (5948417394, –≠—Ç–æ –º–∞—Ç–µ–º–∞—Ç–∏—á–µ—Å–∫–æ–µ –≤—ã—Ä–∞–∂–µ–Ω–∏–µ, –∑–∞–ø–∏—Å–∞–Ω–Ω–æ–µ —Å –∏—Å–ø–æ–ª—å–∑–æ–≤–∞–Ω–∏–µ–º LaTeX ‚Äî —è–∑—ã–∫–∞ —Ä–∞–∑–º–µ—Ç–∫–∏, –∫–æ—Ç–æ—Ä—ã–π —à–∏—Ä–æ–∫–æ –∏—Å–ø–æ–ª—å–∑—É–µ—Ç—Å—è –¥–ª—è –æ—Ñ–æ—Ä–º–ª–µ–Ω–∏—è —Ñ–æ—Ä–º—É–ª –∏ –º–∞—Ç–µ–º–∞—Ç–∏—á–µ—Å–∫–∏—Ö –≤—ã—Ä–∞–∂–µ–Ω–∏–π. –í –¥–∞–Ω–Ω–æ–º —Å–ª—É—á–∞–µ, –≤—ã—Ä–∞–∂–µ–Ω–∏–µ –æ–ø–∏—Å—ã–≤–∞–µ—Ç, –∫–∞–∫ –≤—ã—á–∏—Å–ª—è–µ—Ç—Å—è —Å–∏–Ω—É—Å —É–≥–ª–∞ Œ∏ –≤ –ø—Ä—è–º–æ—É–≥–æ–ª—å–Ω–æ–º —Ç—Ä–µ—É–≥–æ–ª—å–Ω–∏–∫–µ. 

–ß—Ç–æ–±—ã –æ–±—ä—è—Å–Ω–∏—Ç—å –ø–æ-–ø—Ä–æ—Å—Ç–æ–º—É:
- \( \sin(\theta) \) ‚Äî —ç—Ç–æ —Å–∏–Ω—É—Å —É–≥–ª–∞ Œ∏.
- "–î–ª–∏–Ω–∞ –ø—Ä–æ—Ç–∏–≤–æ–ª–µ–∂–∞—â–µ–≥–æ –∫–∞—Ç–µ—Ç–∞" ‚Äî —ç—Ç–æ –¥–ª–∏–Ω–∞ —Å—Ç–æ—Ä–æ–Ω—ã —Ç—Ä–µ—É–≥–æ–ª—å–Ω–∏–∫–∞, –∫–æ—Ç–æ—Ä–∞—è –Ω–∞—Ö–æ–¥–∏—Ç—Å—è –Ω–∞–ø—Ä–æ—Ç–∏–≤ —É–≥–ª–∞ Œ∏.
- "–î–ª–∏–Ω–∞ –≥–∏–ø–æ—Ç–µ–Ω—É–∑—ã" ‚Äî —ç—Ç–æ –¥–ª–∏–Ω–∞ —Å–∞–º–æ–π –¥–ª–∏–Ω–Ω–æ–π —Å—Ç–æ—Ä–æ–Ω—ã —Ç—Ä–µ—É–≥–æ–ª—å–Ω–∏–∫–∞.

–°–æ–æ—Ç–Ω–æ—à–µ–Ω–∏–µ –ø–æ–∫–∞–∑—ã–≤–∞–µ—Ç, —á—Ç–æ —Å–∏–Ω—É—Å —É–≥–ª–∞ —Ä–∞–≤–µ–Ω –æ—Ç–Ω–æ—à–µ–Ω–∏—é –¥–ª–∏–Ω—ã –ø—Ä–æ—Ç–∏–≤–æ–ª–µ–∂–∞—â–µ–≥–æ –∫–∞—Ç–µ—Ç–∞ –∫ –¥–ª–∏–Ω–µ –≥–∏–ø–æ—Ç–µ–Ω—É–∑—ã. –ï—Å–ª–∏ —Ç–µ–±–µ –Ω—É–∂–Ω–æ –±–æ–ª—å—à–µ –∏–Ω—Ñ–æ—Ä–º–∞—Ü–∏–∏ –∏–ª–∏ –ø—Ä–∏–º–µ—Ä–æ–≤, –¥–∞–π –∑–Ω–∞—Ç—å!, assistant, 185)
2025-01-30 17 - TeleBot - ERROR - Infinity polling: polling exited
2025-01-30 17 - TeleBot - ERROR - Break infinity polling
2025-01-30 18 - root - INFO - DATABASE: INSERT INTO messages VALUES (5948417394, –Ω–∞–ø–∏—à–∏ –º–Ω–µ –ª—é–±—É—é —Ñ–æ—Ä–º—É–ª—É, –∏—Å–ø–æ–ª—å–∑—É—è latex, user, 0)
2025-01-30 18 - TeleBot - ERROR - Threaded polling exception: A request to the Telegram API was unsuccessful. Error code: 400. Description: Bad Request: can't parse entities: Can't find end of the entity starting at byte offset 383
2025-01-30 18 - TeleBot - ERROR - Exception traceback:
Traceback (most recent call last):
  File "C:\Users\–¢–∏–º–∞\PycharmProjects\TelegramBot\venv\Lib\site-packages\telebot\__init__.py", line 1235, in __threaded_polling
    self.worker_pool.raise_exceptions()
    ~~~~~~~~~~~~~~~~~~~~~~~~~~~~~~~~~^^
  File "C:\Users\–¢–∏–º–∞\PycharmProjects\TelegramBot\venv\Lib\site-packages\telebot\util.py", line 150, in raise_exceptions
    raise self.exception_info
  File "C:\Users\–¢–∏–º–∞\PycharmProjects\TelegramBot\venv\Lib\site-packages\telebot\util.py", line 93, in run
    task(*args, **kwargs)
    ~~~~^^^^^^^^^^^^^^^^^
  File "C:\Users\–¢–∏–º–∞\PycharmProjects\TelegramBot\venv\Lib\site-packages\telebot\__init__.py", line 9233, in _run_middlewares_and_handler
    result = handler['function'](message)
  File "C:\Users\–¢–∏–º–∞\PycharmProjects\TelegramBot\main.py", line 61, in handle_text
    bot.send_message(user_id, answer + str(answer_tokens), parse_mode='markdown')
    ~~~~~~~~~~~~~~~~^^^^^^^^^^^^^^^^^^^^^^^^^^^^^^^^^^^^^^^^^^^^^^^^^^^^^^^^^^^^^
  File "C:\Users\–¢–∏–º–∞\PycharmProjects\TelegramBot\venv\Lib\site-packages\telebot\__init__.py", line 1800, in send_message
    apihelper.send_message(
    ~~~~~~~~~~~~~~~~~~~~~~^
        self.token, chat_id, text,
        ^^^^^^^^^^^^^^^^^^^^^^^^^^
    ...<2 lines>...
        reply_parameters=reply_parameters, link_preview_options=link_preview_options, business_connection_id=business_connection_id,
        ^^^^^^^^^^^^^^^^^^^^^^^^^^^^^^^^^^^^^^^^^^^^^^^^^^^^^^^^^^^^^^^^^^^^^^^^^^^^^^^^^^^^^^^^^^^^^^^^^^^^^^^^^^^^^^^^^^^^^^^^^^^^
        message_effect_id=message_effect_id, allow_paid_broadcast=allow_paid_broadcast))
        ^^^^^^^^^^^^^^^^^^^^^^^^^^^^^^^^^^^^^^^^^^^^^^^^^^^^^^^^^^^^^^^^^^^^^^^^^^^^^^^
  File "C:\Users\–¢–∏–º–∞\PycharmProjects\TelegramBot\venv\Lib\site-packages\telebot\apihelper.py", line 275, in send_message
    return _make_request(token, method_url, params=payload, method='post')
  File "C:\Users\–¢–∏–º–∞\PycharmProjects\TelegramBot\venv\Lib\site-packages\telebot\apihelper.py", line 168, in _make_request
    json_result = _check_result(method_name, result)
  File "C:\Users\–¢–∏–º–∞\PycharmProjects\TelegramBot\venv\Lib\site-packages\telebot\apihelper.py", line 195, in _check_result
    raise ApiTelegramException(method_name, result, result_json)
telebot.apihelper.ApiTelegramException: A request to the Telegram API was unsuccessful. Error code: 400. Description: Bad Request: can't parse entities: Can't find end of the entity starting at byte offset 383

2025-01-30 18 - TeleBot - ERROR - Infinity polling: polling exited
2025-01-30 18 - TeleBot - ERROR - Break infinity polling
2025-01-30 18 - root - INFO - DATABASE: INSERT INTO messages VALUES (5948417394, –Ω–∞–ø–∏—à–∏ –º–Ω–µ —Ñ–æ—Ä–º—É–ª—É latex, user, 0)
2025-01-30 18 - TeleBot - ERROR - Infinity polling exception: ('Connection aborted.', RemoteDisconnected('Remote end closed connection without response'))
2025-01-30 18 - TeleBot - ERROR - Exception traceback:
Traceback (most recent call last):
  File "C:\Users\–¢–∏–º–∞\PycharmProjects\TelegramBot\venv\Lib\site-packages\urllib3\connectionpool.py", line 787, in urlopen
    response = self._make_request(
        conn,
    ...<10 lines>...
        **response_kw,
    )
  File "C:\Users\–¢–∏–º–∞\PycharmProjects\TelegramBot\venv\Lib\site-packages\urllib3\connectionpool.py", line 534, in _make_request
    response = conn.getresponse()
  File "C:\Users\–¢–∏–º–∞\PycharmProjects\TelegramBot\venv\Lib\site-packages\urllib3\connection.py", line 516, in getresponse
    httplib_response = super().getresponse()
  File "C:\Program Files\Python313\Lib\http\client.py", line 1428, in getresponse
    response.begin()
    ~~~~~~~~~~~~~~^^
  File "C:\Program Files\Python313\Lib\http\client.py", line 331, in begin
    version, status, reason = self._read_status()
                              ~~~~~~~~~~~~~~~~~^^
  File "C:\Program Files\Python313\Lib\http\client.py", line 300, in _read_status
    raise RemoteDisconnected("Remote end closed connection without"
                             " response")
http.client.RemoteDisconnected: Remote end closed connection without response

During handling of the above exception, another exception occurred:

Traceback (most recent call last):
  File "C:\Users\–¢–∏–º–∞\PycharmProjects\TelegramBot\venv\Lib\site-packages\requests\adapters.py", line 667, in send
    resp = conn.urlopen(
        method=request.method,
    ...<9 lines>...
        chunked=chunked,
    )
  File "C:\Users\–¢–∏–º–∞\PycharmProjects\TelegramBot\venv\Lib\site-packages\urllib3\connectionpool.py", line 841, in urlopen
    retries = retries.increment(
        method, url, error=new_e, _pool=self, _stacktrace=sys.exc_info()[2]
    )
  File "C:\Users\–¢–∏–º–∞\PycharmProjects\TelegramBot\venv\Lib\site-packages\urllib3\util\retry.py", line 474, in increment
    raise reraise(type(error), error, _stacktrace)
          ~~~~~~~^^^^^^^^^^^^^^^^^^^^^^^^^^^^^^^^^
  File "C:\Users\–¢–∏–º–∞\PycharmProjects\TelegramBot\venv\Lib\site-packages\urllib3\util\util.py", line 38, in reraise
    raise value.with_traceback(tb)
  File "C:\Users\–¢–∏–º–∞\PycharmProjects\TelegramBot\venv\Lib\site-packages\urllib3\connectionpool.py", line 787, in urlopen
    response = self._make_request(
        conn,
    ...<10 lines>...
        **response_kw,
    )
  File "C:\Users\–¢–∏–º–∞\PycharmProjects\TelegramBot\venv\Lib\site-packages\urllib3\connectionpool.py", line 534, in _make_request
    response = conn.getresponse()
  File "C:\Users\–¢–∏–º–∞\PycharmProjects\TelegramBot\venv\Lib\site-packages\urllib3\connection.py", line 516, in getresponse
    httplib_response = super().getresponse()
  File "C:\Program Files\Python313\Lib\http\client.py", line 1428, in getresponse
    response.begin()
    ~~~~~~~~~~~~~~^^
  File "C:\Program Files\Python313\Lib\http\client.py", line 331, in begin
    version, status, reason = self._read_status()
                              ~~~~~~~~~~~~~~~~~^^
  File "C:\Program Files\Python313\Lib\http\client.py", line 300, in _read_status
    raise RemoteDisconnected("Remote end closed connection without"
                             " response")
urllib3.exceptions.ProtocolError: ('Connection aborted.', RemoteDisconnected('Remote end closed connection without response'))

During handling of the above exception, another exception occurred:

Traceback (most recent call last):
  File "C:\Users\–¢–∏–º–∞\PycharmProjects\TelegramBot\venv\Lib\site-packages\telebot\__init__.py", line 1110, in infinity_polling
    self.polling(non_stop=True, timeout=timeout, long_polling_timeout=long_polling_timeout,
    ~~~~~~~~~~~~^^^^^^^^^^^^^^^^^^^^^^^^^^^^^^^^^^^^^^^^^^^^^^^^^^^^^^^^^^^^^^^^^^^^^^^^^^^
                 logger_level=logger_level, allowed_updates=allowed_updates, restart_on_change=False,
                 ^^^^^^^^^^^^^^^^^^^^^^^^^^^^^^^^^^^^^^^^^^^^^^^^^^^^^^^^^^^^^^^^^^^^^^^^^^^^^^^^^^^^
                 *args, **kwargs)
                 ^^^^^^^^^^^^^^^^
  File "C:\Users\–¢–∏–º–∞\PycharmProjects\TelegramBot\venv\Lib\site-packages\telebot\__init__.py", line 1198, in polling
    self.__threaded_polling(non_stop=non_stop, interval=interval, timeout=timeout, long_polling_timeout=long_polling_timeout,
    ~~~~~~~~~~~~~~~~~~~~~~~^^^^^^^^^^^^^^^^^^^^^^^^^^^^^^^^^^^^^^^^^^^^^^^^^^^^^^^^^^^^^^^^^^^^^^^^^^^^^^^^^^^^^^^^^^^^^^^^^^
                            logger_level=logger_level, allowed_updates=allowed_updates)
                            ^^^^^^^^^^^^^^^^^^^^^^^^^^^^^^^^^^^^^^^^^^^^^^^^^^^^^^^^^^^
  File "C:\Users\–¢–∏–º–∞\PycharmProjects\TelegramBot\venv\Lib\site-packages\telebot\__init__.py", line 1273, in __threaded_polling
    raise e
  File "C:\Users\–¢–∏–º–∞\PycharmProjects\TelegramBot\venv\Lib\site-packages\telebot\__init__.py", line 1235, in __threaded_polling
    self.worker_pool.raise_exceptions()
    ~~~~~~~~~~~~~~~~~~~~~~~~~~~~~~~~~^^
  File "C:\Users\–¢–∏–º–∞\PycharmProjects\TelegramBot\venv\Lib\site-packages\telebot\util.py", line 150, in raise_exceptions
    raise self.exception_info
  File "C:\Users\–¢–∏–º–∞\PycharmProjects\TelegramBot\venv\Lib\site-packages\telebot\util.py", line 93, in run
    task(*args, **kwargs)
    ~~~~^^^^^^^^^^^^^^^^^
  File "C:\Users\–¢–∏–º–∞\PycharmProjects\TelegramBot\venv\Lib\site-packages\telebot\__init__.py", line 9233, in _run_middlewares_and_handler
    result = handler['function'](message)
  File "C:\Users\–¢–∏–º–∞\PycharmProjects\TelegramBot\main.py", line 61, in handle_text
    bot.send_message(user_id, answer + str(answer_tokens))
    ~~~~~~~~~~~~~~~~^^^^^^^^^^^^^^^^^^^^^^^^^^^^^^^^^^^^^^
  File "C:\Users\–¢–∏–º–∞\PycharmProjects\TelegramBot\venv\Lib\site-packages\telebot\__init__.py", line 1800, in send_message
    apihelper.send_message(
    ~~~~~~~~~~~~~~~~~~~~~~^
        self.token, chat_id, text,
        ^^^^^^^^^^^^^^^^^^^^^^^^^^
    ...<2 lines>...
        reply_parameters=reply_parameters, link_preview_options=link_preview_options, business_connection_id=business_connection_id,
        ^^^^^^^^^^^^^^^^^^^^^^^^^^^^^^^^^^^^^^^^^^^^^^^^^^^^^^^^^^^^^^^^^^^^^^^^^^^^^^^^^^^^^^^^^^^^^^^^^^^^^^^^^^^^^^^^^^^^^^^^^^^^
        message_effect_id=message_effect_id, allow_paid_broadcast=allow_paid_broadcast))
        ^^^^^^^^^^^^^^^^^^^^^^^^^^^^^^^^^^^^^^^^^^^^^^^^^^^^^^^^^^^^^^^^^^^^^^^^^^^^^^^
  File "C:\Users\–¢–∏–º–∞\PycharmProjects\TelegramBot\venv\Lib\site-packages\telebot\apihelper.py", line 275, in send_message
    return _make_request(token, method_url, params=payload, method='post')
  File "C:\Users\–¢–∏–º–∞\PycharmProjects\TelegramBot\venv\Lib\site-packages\telebot\apihelper.py", line 162, in _make_request
    result = _get_req_session().request(
        method, request_url, params=params, files=files,
        timeout=(connect_timeout, read_timeout), proxies=proxy)
  File "C:\Users\–¢–∏–º–∞\PycharmProjects\TelegramBot\venv\Lib\site-packages\requests\sessions.py", line 589, in request
    resp = self.send(prep, **send_kwargs)
  File "C:\Users\–¢–∏–º–∞\PycharmProjects\TelegramBot\venv\Lib\site-packages\requests\sessions.py", line 703, in send
    r = adapter.send(request, **kwargs)
  File "C:\Users\–¢–∏–º–∞\PycharmProjects\TelegramBot\venv\Lib\site-packages\requests\adapters.py", line 682, in send
    raise ConnectionError(err, request=request)
requests.exceptions.ConnectionError: ('Connection aborted.', RemoteDisconnected('Remote end closed connection without response'))

2025-01-30 18 - TeleBot - ERROR - Infinity polling exception: HTTPSConnectionPool(host='api.telegram.org', port=443): Max retries exceeded with url: /bot7221935484:***********************************/getUpdates?offset=901297481&timeout=20 (Caused by SSLError(SSLEOFError(8, '[SSL: UNEXPECTED_EOF_WHILE_READING] EOF occurred in violation of protocol (_ssl.c:1018)')))
2025-01-30 18 - TeleBot - ERROR - Exception traceback:
Traceback (most recent call last):
  File "C:\Users\–¢–∏–º–∞\PycharmProjects\TelegramBot\venv\Lib\site-packages\urllib3\connectionpool.py", line 464, in _make_request
    self._validate_conn(conn)
    ~~~~~~~~~~~~~~~~~~~^^^^^^
  File "C:\Users\–¢–∏–º–∞\PycharmProjects\TelegramBot\venv\Lib\site-packages\urllib3\connectionpool.py", line 1093, in _validate_conn
    conn.connect()
    ~~~~~~~~~~~~^^
  File "C:\Users\–¢–∏–º–∞\PycharmProjects\TelegramBot\venv\Lib\site-packages\urllib3\connection.py", line 741, in connect
    sock_and_verified = _ssl_wrap_socket_and_match_hostname(
        sock=sock,
    ...<14 lines>...
        assert_fingerprint=self.assert_fingerprint,
    )
  File "C:\Users\–¢–∏–º–∞\PycharmProjects\TelegramBot\venv\Lib\site-packages\urllib3\connection.py", line 920, in _ssl_wrap_socket_and_match_hostname
    ssl_sock = ssl_wrap_socket(
        sock=sock,
    ...<8 lines>...
        tls_in_tls=tls_in_tls,
    )
  File "C:\Users\–¢–∏–º–∞\PycharmProjects\TelegramBot\venv\Lib\site-packages\urllib3\util\ssl_.py", line 460, in ssl_wrap_socket
    ssl_sock = _ssl_wrap_socket_impl(sock, context, tls_in_tls, server_hostname)
  File "C:\Users\–¢–∏–º–∞\PycharmProjects\TelegramBot\venv\Lib\site-packages\urllib3\util\ssl_.py", line 504, in _ssl_wrap_socket_impl
    return ssl_context.wrap_socket(sock, server_hostname=server_hostname)
           ~~~~~~~~~~~~~~~~~~~~~~~^^^^^^^^^^^^^^^^^^^^^^^^^^^^^^^^^^^^^^^
  File "C:\Program Files\Python313\Lib\ssl.py", line 455, in wrap_socket
    return self.sslsocket_class._create(
           ~~~~~~~~~~~~~~~~~~~~~~~~~~~~^
        sock=sock,
        ^^^^^^^^^^
    ...<5 lines>...
        session=session
        ^^^^^^^^^^^^^^^
    )
    ^
  File "C:\Program Files\Python313\Lib\ssl.py", line 1076, in _create
    self.do_handshake()
    ~~~~~~~~~~~~~~~~~^^
  File "C:\Program Files\Python313\Lib\ssl.py", line 1372, in do_handshake
    self._sslobj.do_handshake()
    ~~~~~~~~~~~~~~~~~~~~~~~~~^^
ssl.SSLEOFError: [SSL: UNEXPECTED_EOF_WHILE_READING] EOF occurred in violation of protocol (_ssl.c:1018)

During handling of the above exception, another exception occurred:

Traceback (most recent call last):
  File "C:\Users\–¢–∏–º–∞\PycharmProjects\TelegramBot\venv\Lib\site-packages\urllib3\connectionpool.py", line 787, in urlopen
    response = self._make_request(
        conn,
    ...<10 lines>...
        **response_kw,
    )
  File "C:\Users\–¢–∏–º–∞\PycharmProjects\TelegramBot\venv\Lib\site-packages\urllib3\connectionpool.py", line 488, in _make_request
    raise new_e
urllib3.exceptions.SSLError: [SSL: UNEXPECTED_EOF_WHILE_READING] EOF occurred in violation of protocol (_ssl.c:1018)

The above exception was the direct cause of the following exception:

Traceback (most recent call last):
  File "C:\Users\–¢–∏–º–∞\PycharmProjects\TelegramBot\venv\Lib\site-packages\requests\adapters.py", line 667, in send
    resp = conn.urlopen(
        method=request.method,
    ...<9 lines>...
        chunked=chunked,
    )
  File "C:\Users\–¢–∏–º–∞\PycharmProjects\TelegramBot\venv\Lib\site-packages\urllib3\connectionpool.py", line 841, in urlopen
    retries = retries.increment(
        method, url, error=new_e, _pool=self, _stacktrace=sys.exc_info()[2]
    )
  File "C:\Users\–¢–∏–º–∞\PycharmProjects\TelegramBot\venv\Lib\site-packages\urllib3\util\retry.py", line 519, in increment
    raise MaxRetryError(_pool, url, reason) from reason  # type: ignore[arg-type]
    ^^^^^^^^^^^^^^^^^^^^^^^^^^^^^^^^^^^^^^^^^^^^^^^^^^^
urllib3.exceptions.MaxRetryError: HTTPSConnectionPool(host='api.telegram.org', port=443): Max retries exceeded with url: /bot7221935484:***********************************/getUpdates?offset=901297481&timeout=20 (Caused by SSLError(SSLEOFError(8, '[SSL: UNEXPECTED_EOF_WHILE_READING] EOF occurred in violation of protocol (_ssl.c:1018)')))

During handling of the above exception, another exception occurred:

Traceback (most recent call last):
  File "C:\Users\–¢–∏–º–∞\PycharmProjects\TelegramBot\venv\Lib\site-packages\telebot\__init__.py", line 1110, in infinity_polling
    self.polling(non_stop=True, timeout=timeout, long_polling_timeout=long_polling_timeout,
    ~~~~~~~~~~~~^^^^^^^^^^^^^^^^^^^^^^^^^^^^^^^^^^^^^^^^^^^^^^^^^^^^^^^^^^^^^^^^^^^^^^^^^^^
                 logger_level=logger_level, allowed_updates=allowed_updates, restart_on_change=False,
                 ^^^^^^^^^^^^^^^^^^^^^^^^^^^^^^^^^^^^^^^^^^^^^^^^^^^^^^^^^^^^^^^^^^^^^^^^^^^^^^^^^^^^
                 *args, **kwargs)
                 ^^^^^^^^^^^^^^^^
  File "C:\Users\–¢–∏–º–∞\PycharmProjects\TelegramBot\venv\Lib\site-packages\telebot\__init__.py", line 1198, in polling
    self.__threaded_polling(non_stop=non_stop, interval=interval, timeout=timeout, long_polling_timeout=long_polling_timeout,
    ~~~~~~~~~~~~~~~~~~~~~~~^^^^^^^^^^^^^^^^^^^^^^^^^^^^^^^^^^^^^^^^^^^^^^^^^^^^^^^^^^^^^^^^^^^^^^^^^^^^^^^^^^^^^^^^^^^^^^^^^^
                            logger_level=logger_level, allowed_updates=allowed_updates)
                            ^^^^^^^^^^^^^^^^^^^^^^^^^^^^^^^^^^^^^^^^^^^^^^^^^^^^^^^^^^^
  File "C:\Users\–¢–∏–º–∞\PycharmProjects\TelegramBot\venv\Lib\site-packages\telebot\__init__.py", line 1273, in __threaded_polling
    raise e
  File "C:\Users\–¢–∏–º–∞\PycharmProjects\TelegramBot\venv\Lib\site-packages\telebot\__init__.py", line 1234, in __threaded_polling
    polling_thread.raise_exceptions()
    ~~~~~~~~~~~~~~~~~~~~~~~~~~~~~~~^^
  File "C:\Users\–¢–∏–º–∞\PycharmProjects\TelegramBot\venv\Lib\site-packages\telebot\util.py", line 111, in raise_exceptions
    raise self.exception_info
  File "C:\Users\–¢–∏–º–∞\PycharmProjects\TelegramBot\venv\Lib\site-packages\telebot\util.py", line 93, in run
    task(*args, **kwargs)
    ~~~~^^^^^^^^^^^^^^^^^
  File "C:\Users\–¢–∏–º–∞\PycharmProjects\TelegramBot\venv\Lib\site-packages\telebot\__init__.py", line 688, in __retrieve_updates
    updates = self.get_updates(offset=(self.last_update_id + 1),
                               allowed_updates=allowed_updates,
                               timeout=timeout, long_polling_timeout=long_polling_timeout)
  File "C:\Users\–¢–∏–º–∞\PycharmProjects\TelegramBot\venv\Lib\site-packages\telebot\__init__.py", line 660, in get_updates
    json_updates = apihelper.get_updates(
        self.token, offset=offset, limit=limit, timeout=timeout, allowed_updates=allowed_updates,
        long_polling_timeout=long_polling_timeout)
  File "C:\Users\–¢–∏–º–∞\PycharmProjects\TelegramBot\venv\Lib\site-packages\telebot\apihelper.py", line 332, in get_updates
    return _make_request(token, method_url, params=payload)
  File "C:\Users\–¢–∏–º–∞\PycharmProjects\TelegramBot\venv\Lib\site-packages\telebot\apihelper.py", line 162, in _make_request
    result = _get_req_session().request(
        method, request_url, params=params, files=files,
        timeout=(connect_timeout, read_timeout), proxies=proxy)
  File "C:\Users\–¢–∏–º–∞\PycharmProjects\TelegramBot\venv\Lib\site-packages\requests\sessions.py", line 589, in request
    resp = self.send(prep, **send_kwargs)
  File "C:\Users\–¢–∏–º–∞\PycharmProjects\TelegramBot\venv\Lib\site-packages\requests\sessions.py", line 703, in send
    r = adapter.send(request, **kwargs)
  File "C:\Users\–¢–∏–º–∞\PycharmProjects\TelegramBot\venv\Lib\site-packages\requests\adapters.py", line 698, in send
    raise SSLError(e, request=request)
requests.exceptions.SSLError: HTTPSConnectionPool(host='api.telegram.org', port=443): Max retries exceeded with url: /bot7221935484:***********************************/getUpdates?offset=901297481&timeout=20 (Caused by SSLError(SSLEOFError(8, '[SSL: UNEXPECTED_EOF_WHILE_READING] EOF occurred in violation of protocol (_ssl.c:1018)')))

2025-01-30 18 - TeleBot - ERROR - Infinity polling: polling exited
2025-01-30 18 - TeleBot - ERROR - Break infinity polling
2025-01-31 18 - TeleBot - ERROR - Infinity polling exception: 'dict' object has no attribute 'add'
2025-01-31 18 - TeleBot - ERROR - Exception traceback:
Traceback (most recent call last):
  File "C:\Users\–¢–∏–º–∞\PycharmProjects\TelegramBot\venv\Lib\site-packages\telebot\__init__.py", line 1110, in infinity_polling
    self.polling(non_stop=True, timeout=timeout, long_polling_timeout=long_polling_timeout,
    ~~~~~~~~~~~~^^^^^^^^^^^^^^^^^^^^^^^^^^^^^^^^^^^^^^^^^^^^^^^^^^^^^^^^^^^^^^^^^^^^^^^^^^^
                 logger_level=logger_level, allowed_updates=allowed_updates, restart_on_change=False,
                 ^^^^^^^^^^^^^^^^^^^^^^^^^^^^^^^^^^^^^^^^^^^^^^^^^^^^^^^^^^^^^^^^^^^^^^^^^^^^^^^^^^^^
                 *args, **kwargs)
                 ^^^^^^^^^^^^^^^^
  File "C:\Users\–¢–∏–º–∞\PycharmProjects\TelegramBot\venv\Lib\site-packages\telebot\__init__.py", line 1198, in polling
    self.__threaded_polling(non_stop=non_stop, interval=interval, timeout=timeout, long_polling_timeout=long_polling_timeout,
    ~~~~~~~~~~~~~~~~~~~~~~~^^^^^^^^^^^^^^^^^^^^^^^^^^^^^^^^^^^^^^^^^^^^^^^^^^^^^^^^^^^^^^^^^^^^^^^^^^^^^^^^^^^^^^^^^^^^^^^^^^
                            logger_level=logger_level, allowed_updates=allowed_updates)
                            ^^^^^^^^^^^^^^^^^^^^^^^^^^^^^^^^^^^^^^^^^^^^^^^^^^^^^^^^^^^
  File "C:\Users\–¢–∏–º–∞\PycharmProjects\TelegramBot\venv\Lib\site-packages\telebot\__init__.py", line 1273, in __threaded_polling
    raise e
  File "C:\Users\–¢–∏–º–∞\PycharmProjects\TelegramBot\venv\Lib\site-packages\telebot\__init__.py", line 1235, in __threaded_polling
    self.worker_pool.raise_exceptions()
    ~~~~~~~~~~~~~~~~~~~~~~~~~~~~~~~~~^^
  File "C:\Users\–¢–∏–º–∞\PycharmProjects\TelegramBot\venv\Lib\site-packages\telebot\util.py", line 150, in raise_exceptions
    raise self.exception_info
  File "C:\Users\–¢–∏–º–∞\PycharmProjects\TelegramBot\venv\Lib\site-packages\telebot\util.py", line 93, in run
    task(*args, **kwargs)
    ~~~~^^^^^^^^^^^^^^^^^
  File "C:\Users\–¢–∏–º–∞\PycharmProjects\TelegramBot\venv\Lib\site-packages\telebot\__init__.py", line 9233, in _run_middlewares_and_handler
    result = handler['function'](message)
  File "C:\Users\–¢–∏–º–∞\PycharmProjects\TelegramBot\main.py", line 65, in show_settings
    send_welcome(msg)
    ~~~~~~~~~~~~^^^^^
  File "C:\Users\–¢–∏–º–∞\PycharmProjects\TelegramBot\main.py", line 32, in send_welcome
    add_user(user_id=msg.chat.id)
    ~~~~~~~~^^^^^^^^^^^^^^^^^^^^^
  File "C:\Users\–¢–∏–º–∞\PycharmProjects\TelegramBot\main.py", line 23, in add_user
    settings.add({
    ^^^^^^^^^^^^
AttributeError: 'dict' object has no attribute 'add'

2025-01-31 18 - TeleBot - ERROR - Infinity polling: polling exited
2025-01-31 18 - TeleBot - ERROR - Break infinity polling
2025-01-31 18 - TeleBot - ERROR - Infinity polling exception: 'dict' object has no attribute 'append'
2025-01-31 18 - TeleBot - ERROR - Exception traceback:
Traceback (most recent call last):
  File "C:\Users\–¢–∏–º–∞\PycharmProjects\TelegramBot\venv\Lib\site-packages\telebot\__init__.py", line 1110, in infinity_polling
    self.polling(non_stop=True, timeout=timeout, long_polling_timeout=long_polling_timeout,
    ~~~~~~~~~~~~^^^^^^^^^^^^^^^^^^^^^^^^^^^^^^^^^^^^^^^^^^^^^^^^^^^^^^^^^^^^^^^^^^^^^^^^^^^
                 logger_level=logger_level, allowed_updates=allowed_updates, restart_on_change=False,
                 ^^^^^^^^^^^^^^^^^^^^^^^^^^^^^^^^^^^^^^^^^^^^^^^^^^^^^^^^^^^^^^^^^^^^^^^^^^^^^^^^^^^^
                 *args, **kwargs)
                 ^^^^^^^^^^^^^^^^
  File "C:\Users\–¢–∏–º–∞\PycharmProjects\TelegramBot\venv\Lib\site-packages\telebot\__init__.py", line 1198, in polling
    self.__threaded_polling(non_stop=non_stop, interval=interval, timeout=timeout, long_polling_timeout=long_polling_timeout,
    ~~~~~~~~~~~~~~~~~~~~~~~^^^^^^^^^^^^^^^^^^^^^^^^^^^^^^^^^^^^^^^^^^^^^^^^^^^^^^^^^^^^^^^^^^^^^^^^^^^^^^^^^^^^^^^^^^^^^^^^^^
                            logger_level=logger_level, allowed_updates=allowed_updates)
                            ^^^^^^^^^^^^^^^^^^^^^^^^^^^^^^^^^^^^^^^^^^^^^^^^^^^^^^^^^^^
  File "C:\Users\–¢–∏–º–∞\PycharmProjects\TelegramBot\venv\Lib\site-packages\telebot\__init__.py", line 1273, in __threaded_polling
    raise e
  File "C:\Users\–¢–∏–º–∞\PycharmProjects\TelegramBot\venv\Lib\site-packages\telebot\__init__.py", line 1235, in __threaded_polling
    self.worker_pool.raise_exceptions()
    ~~~~~~~~~~~~~~~~~~~~~~~~~~~~~~~~~^^
  File "C:\Users\–¢–∏–º–∞\PycharmProjects\TelegramBot\venv\Lib\site-packages\telebot\util.py", line 150, in raise_exceptions
    raise self.exception_info
  File "C:\Users\–¢–∏–º–∞\PycharmProjects\TelegramBot\venv\Lib\site-packages\telebot\util.py", line 93, in run
    task(*args, **kwargs)
    ~~~~^^^^^^^^^^^^^^^^^
  File "C:\Users\–¢–∏–º–∞\PycharmProjects\TelegramBot\venv\Lib\site-packages\telebot\__init__.py", line 9233, in _run_middlewares_and_handler
    result = handler['function'](message)
  File "C:\Users\–¢–∏–º–∞\PycharmProjects\TelegramBot\main.py", line 66, in show_settings
    send_welcome(msg)
    ~~~~~~~~~~~~^^^^^
  File "C:\Users\–¢–∏–º–∞\PycharmProjects\TelegramBot\main.py", line 32, in send_welcome
    add_user(user_id=msg.chat.id)
    ~~~~~~~~^^^^^^^^^^^^^^^^^^^^^
  File "C:\Users\–¢–∏–º–∞\PycharmProjects\TelegramBot\main.py", line 23, in add_user
    settings.append({
    ^^^^^^^^^^^^^^^
AttributeError: 'dict' object has no attribute 'append'

2025-01-31 18 - TeleBot - ERROR - Infinity polling: polling exited
2025-01-31 18 - TeleBot - ERROR - Break infinity polling
2025-01-31 18 - root - INFO - DATABASE: INSERT INTO messages VALUES (5948417394, /feedback, user, 0)
2025-01-31 18 - root - INFO - DATABASE: INSERT INTO messages VALUES (5948417394, –ö–æ–Ω–µ—á–Ω–æ! –í–æ—Ç –ø—Ä–æ—Å—Ç–æ–π –ø—Ä–∏–º–µ—Ä —Ñ–æ—Ä–º—É–ª—ã –Ω–∞ LaTeX, –∫–æ—Ç–æ—Ä–∞—è –æ–ø–∏—Å—ã–≤–∞–µ—Ç –∫–≤–∞–¥—Ä–∞—Ç–Ω–æ–µ —É—Ä–∞–≤–Ω–µ–Ω–∏–µ:

\[ ax^2 + bx + c = 0 \]

–ï—Å–ª–∏ —Ç–µ–±–µ –Ω—É–∂–Ω–∞ –∫–æ–Ω–∫—Ä–µ—Ç–Ω–∞—è —Ñ–æ—Ä–º—É–ª–∞ –∏–ª–∏ –æ–ø—Ä–µ–¥–µ–ª—ë–Ω–Ω–∞—è —Ç–µ–º–∞, –¥–∞–π –∑–Ω–∞—Ç—å!, assistant, 51)
2025-01-31 18 - TeleBot - ERROR - Infinity polling: polling exited
2025-01-31 18 - TeleBot - ERROR - Break infinity polling
2025-01-31 18 - TeleBot - ERROR - Infinity polling exception: too many values to unpack (expected 2)
2025-01-31 18 - TeleBot - ERROR - Exception traceback:
Traceback (most recent call last):
  File "C:\Users\–¢–∏–º–∞\PycharmProjects\TelegramBot\venv\Lib\site-packages\telebot\__init__.py", line 1110, in infinity_polling
    self.polling(non_stop=True, timeout=timeout, long_polling_timeout=long_polling_timeout,
    ~~~~~~~~~~~~^^^^^^^^^^^^^^^^^^^^^^^^^^^^^^^^^^^^^^^^^^^^^^^^^^^^^^^^^^^^^^^^^^^^^^^^^^^
                 logger_level=logger_level, allowed_updates=allowed_updates, restart_on_change=False,
                 ^^^^^^^^^^^^^^^^^^^^^^^^^^^^^^^^^^^^^^^^^^^^^^^^^^^^^^^^^^^^^^^^^^^^^^^^^^^^^^^^^^^^
                 *args, **kwargs)
                 ^^^^^^^^^^^^^^^^
  File "C:\Users\–¢–∏–º–∞\PycharmProjects\TelegramBot\venv\Lib\site-packages\telebot\__init__.py", line 1198, in polling
    self.__threaded_polling(non_stop=non_stop, interval=interval, timeout=timeout, long_polling_timeout=long_polling_timeout,
    ~~~~~~~~~~~~~~~~~~~~~~~^^^^^^^^^^^^^^^^^^^^^^^^^^^^^^^^^^^^^^^^^^^^^^^^^^^^^^^^^^^^^^^^^^^^^^^^^^^^^^^^^^^^^^^^^^^^^^^^^^
                            logger_level=logger_level, allowed_updates=allowed_updates)
                            ^^^^^^^^^^^^^^^^^^^^^^^^^^^^^^^^^^^^^^^^^^^^^^^^^^^^^^^^^^^
  File "C:\Users\–¢–∏–º–∞\PycharmProjects\TelegramBot\venv\Lib\site-packages\telebot\__init__.py", line 1273, in __threaded_polling
    raise e
  File "C:\Users\–¢–∏–º–∞\PycharmProjects\TelegramBot\venv\Lib\site-packages\telebot\__init__.py", line 1235, in __threaded_polling
    self.worker_pool.raise_exceptions()
    ~~~~~~~~~~~~~~~~~~~~~~~~~~~~~~~~~^^
  File "C:\Users\–¢–∏–º–∞\PycharmProjects\TelegramBot\venv\Lib\site-packages\telebot\util.py", line 150, in raise_exceptions
    raise self.exception_info
  File "C:\Users\–¢–∏–º–∞\PycharmProjects\TelegramBot\venv\Lib\site-packages\telebot\util.py", line 93, in run
    task(*args, **kwargs)
    ~~~~^^^^^^^^^^^^^^^^^
  File "C:\Users\–¢–∏–º–∞\PycharmProjects\TelegramBot\venv\Lib\site-packages\telebot\__init__.py", line 9233, in _run_middlewares_and_handler
    result = handler['function'](message)
  File "C:\Users\–¢–∏–º–∞\PycharmProjects\TelegramBot\main.py", line 71, in show_settings
    for k, v in settings[user_id]:
        ^^^^
ValueError: too many values to unpack (expected 2)

2025-01-31 18 - TeleBot - ERROR - Infinity polling: polling exited
2025-01-31 18 - TeleBot - ERROR - Break infinity polling
2025-01-31 18 - TeleBot - ERROR - Threaded polling exception: A request to the Telegram API was unsuccessful. Error code: 400. Description: Bad Request: unsupported parse_mode
2025-01-31 18 - TeleBot - ERROR - Exception traceback:
Traceback (most recent call last):
  File "C:\Users\–¢–∏–º–∞\PycharmProjects\TelegramBot\venv\Lib\site-packages\telebot\__init__.py", line 1235, in __threaded_polling
    self.worker_pool.raise_exceptions()
    ~~~~~~~~~~~~~~~~~~~~~~~~~~~~~~~~~^^
  File "C:\Users\–¢–∏–º–∞\PycharmProjects\TelegramBot\venv\Lib\site-packages\telebot\util.py", line 150, in raise_exceptions
    raise self.exception_info
  File "C:\Users\–¢–∏–º–∞\PycharmProjects\TelegramBot\venv\Lib\site-packages\telebot\util.py", line 93, in run
    task(*args, **kwargs)
    ~~~~^^^^^^^^^^^^^^^^^
  File "C:\Users\–¢–∏–º–∞\PycharmProjects\TelegramBot\venv\Lib\site-packages\telebot\__init__.py", line 9233, in _run_middlewares_and_handler
    result = handler['function'](message)
  File "C:\Users\–¢–∏–º–∞\PycharmProjects\TelegramBot\main.py", line 74, in show_settings
    bot.send_message(user_id, f'–í–∞—à–∏ –Ω–∞—Å—Ç—Ä–æ–π–∫–∏: {usr_st}', create_keyboard(('–ò–∑–º–µ–Ω–∏—Ç—å –Ω–∞—Å—Ç—Ä–æ–π–∫–∏', "–ù–∞–∑–∞–¥")))
    ~~~~~~~~~~~~~~~~^^^^^^^^^^^^^^^^^^^^^^^^^^^^^^^^^^^^^^^^^^^^^^^^^^^^^^^^^^^^^^^^^^^^^^^^^^^^^^^^^^^^^^^^
  File "C:\Users\–¢–∏–º–∞\PycharmProjects\TelegramBot\venv\Lib\site-packages\telebot\__init__.py", line 1800, in send_message
    apihelper.send_message(
    ~~~~~~~~~~~~~~~~~~~~~~^
        self.token, chat_id, text,
        ^^^^^^^^^^^^^^^^^^^^^^^^^^
    ...<2 lines>...
        reply_parameters=reply_parameters, link_preview_options=link_preview_options, business_connection_id=business_connection_id,
        ^^^^^^^^^^^^^^^^^^^^^^^^^^^^^^^^^^^^^^^^^^^^^^^^^^^^^^^^^^^^^^^^^^^^^^^^^^^^^^^^^^^^^^^^^^^^^^^^^^^^^^^^^^^^^^^^^^^^^^^^^^^^
        message_effect_id=message_effect_id, allow_paid_broadcast=allow_paid_broadcast))
        ^^^^^^^^^^^^^^^^^^^^^^^^^^^^^^^^^^^^^^^^^^^^^^^^^^^^^^^^^^^^^^^^^^^^^^^^^^^^^^^
  File "C:\Users\–¢–∏–º–∞\PycharmProjects\TelegramBot\venv\Lib\site-packages\telebot\apihelper.py", line 275, in send_message
    return _make_request(token, method_url, params=payload, method='post')
  File "C:\Users\–¢–∏–º–∞\PycharmProjects\TelegramBot\venv\Lib\site-packages\telebot\apihelper.py", line 168, in _make_request
    json_result = _check_result(method_name, result)
  File "C:\Users\–¢–∏–º–∞\PycharmProjects\TelegramBot\venv\Lib\site-packages\telebot\apihelper.py", line 195, in _check_result
    raise ApiTelegramException(method_name, result, result_json)
telebot.apihelper.ApiTelegramException: A request to the Telegram API was unsuccessful. Error code: 400. Description: Bad Request: unsupported parse_mode

2025-01-31 18 - TeleBot - ERROR - Infinity polling: polling exited
2025-01-31 18 - TeleBot - ERROR - Break infinity polling
2025-01-31 18 - TeleBot - ERROR - Threaded polling exception: A request to the Telegram API was unsuccessful. Error code: 400. Description: Bad Request: unsupported parse_mode
2025-01-31 18 - TeleBot - ERROR - Exception traceback:
Traceback (most recent call last):
  File "C:\Users\–¢–∏–º–∞\PycharmProjects\TelegramBot\venv\Lib\site-packages\telebot\__init__.py", line 1235, in __threaded_polling
    self.worker_pool.raise_exceptions()
    ~~~~~~~~~~~~~~~~~~~~~~~~~~~~~~~~~^^
  File "C:\Users\–¢–∏–º–∞\PycharmProjects\TelegramBot\venv\Lib\site-packages\telebot\util.py", line 150, in raise_exceptions
    raise self.exception_info
  File "C:\Users\–¢–∏–º–∞\PycharmProjects\TelegramBot\venv\Lib\site-packages\telebot\util.py", line 93, in run
    task(*args, **kwargs)
    ~~~~^^^^^^^^^^^^^^^^^
  File "C:\Users\–¢–∏–º–∞\PycharmProjects\TelegramBot\venv\Lib\site-packages\telebot\__init__.py", line 9233, in _run_middlewares_and_handler
    result = handler['function'](message)
  File "C:\Users\–¢–∏–º–∞\PycharmProjects\TelegramBot\main.py", line 75, in show_settings
    bot.send_message(user_id, f'–í–∞—à–∏ –Ω–∞—Å—Ç—Ä–æ–π–∫–∏: {usr_st}', create_keyboard(('–ò–∑–º–µ–Ω–∏—Ç—å –Ω–∞—Å—Ç—Ä–æ–π–∫–∏', "–ù–∞–∑–∞–¥")))
    ~~~~~~~~~~~~~~~~^^^^^^^^^^^^^^^^^^^^^^^^^^^^^^^^^^^^^^^^^^^^^^^^^^^^^^^^^^^^^^^^^^^^^^^^^^^^^^^^^^^^^^^^
  File "C:\Users\–¢–∏–º–∞\PycharmProjects\TelegramBot\venv\Lib\site-packages\telebot\__init__.py", line 1800, in send_message
    apihelper.send_message(
    ~~~~~~~~~~~~~~~~~~~~~~^
        self.token, chat_id, text,
        ^^^^^^^^^^^^^^^^^^^^^^^^^^
    ...<2 lines>...
        reply_parameters=reply_parameters, link_preview_options=link_preview_options, business_connection_id=business_connection_id,
        ^^^^^^^^^^^^^^^^^^^^^^^^^^^^^^^^^^^^^^^^^^^^^^^^^^^^^^^^^^^^^^^^^^^^^^^^^^^^^^^^^^^^^^^^^^^^^^^^^^^^^^^^^^^^^^^^^^^^^^^^^^^^
        message_effect_id=message_effect_id, allow_paid_broadcast=allow_paid_broadcast))
        ^^^^^^^^^^^^^^^^^^^^^^^^^^^^^^^^^^^^^^^^^^^^^^^^^^^^^^^^^^^^^^^^^^^^^^^^^^^^^^^
  File "C:\Users\–¢–∏–º–∞\PycharmProjects\TelegramBot\venv\Lib\site-packages\telebot\apihelper.py", line 275, in send_message
    return _make_request(token, method_url, params=payload, method='post')
  File "C:\Users\–¢–∏–º–∞\PycharmProjects\TelegramBot\venv\Lib\site-packages\telebot\apihelper.py", line 168, in _make_request
    json_result = _check_result(method_name, result)
  File "C:\Users\–¢–∏–º–∞\PycharmProjects\TelegramBot\venv\Lib\site-packages\telebot\apihelper.py", line 195, in _check_result
    raise ApiTelegramException(method_name, result, result_json)
telebot.apihelper.ApiTelegramException: A request to the Telegram API was unsuccessful. Error code: 400. Description: Bad Request: unsupported parse_mode

2025-01-31 18 - root - INFO - DATABASE: INSERT INTO messages VALUES (5948417394, model, user, 0)
2025-01-31 18 - TeleBot - ERROR - Infinity polling: polling exited
2025-01-31 18 - TeleBot - ERROR - Break infinity polling
2025-01-31 18 - TeleBot - ERROR - Infinity polling: polling exited
2025-01-31 18 - TeleBot - ERROR - Break infinity polling
2025-01-31 19 - TeleBot - ERROR - Infinity polling: polling exited
2025-01-31 19 - TeleBot - ERROR - Break infinity polling
2025-01-31 19 - TeleBot - ERROR - Infinity polling exception: '–ú–æ–¥–µ–ª—å –Ω–µ–π—Ä–æ—Å–µ—Ç–∏'
2025-01-31 19 - TeleBot - ERROR - Exception traceback:
Traceback (most recent call last):
  File "C:\Users\–¢–∏–º–∞\PycharmProjects\TelegramBot\venv\Lib\site-packages\telebot\__init__.py", line 1110, in infinity_polling
    self.polling(non_stop=True, timeout=timeout, long_polling_timeout=long_polling_timeout,
    ~~~~~~~~~~~~^^^^^^^^^^^^^^^^^^^^^^^^^^^^^^^^^^^^^^^^^^^^^^^^^^^^^^^^^^^^^^^^^^^^^^^^^^^
                 logger_level=logger_level, allowed_updates=allowed_updates, restart_on_change=False,
                 ^^^^^^^^^^^^^^^^^^^^^^^^^^^^^^^^^^^^^^^^^^^^^^^^^^^^^^^^^^^^^^^^^^^^^^^^^^^^^^^^^^^^
                 *args, **kwargs)
                 ^^^^^^^^^^^^^^^^
  File "C:\Users\–¢–∏–º–∞\PycharmProjects\TelegramBot\venv\Lib\site-packages\telebot\__init__.py", line 1198, in polling
    self.__threaded_polling(non_stop=non_stop, interval=interval, timeout=timeout, long_polling_timeout=long_polling_timeout,
    ~~~~~~~~~~~~~~~~~~~~~~~^^^^^^^^^^^^^^^^^^^^^^^^^^^^^^^^^^^^^^^^^^^^^^^^^^^^^^^^^^^^^^^^^^^^^^^^^^^^^^^^^^^^^^^^^^^^^^^^^^
                            logger_level=logger_level, allowed_updates=allowed_updates)
                            ^^^^^^^^^^^^^^^^^^^^^^^^^^^^^^^^^^^^^^^^^^^^^^^^^^^^^^^^^^^
  File "C:\Users\–¢–∏–º–∞\PycharmProjects\TelegramBot\venv\Lib\site-packages\telebot\__init__.py", line 1273, in __threaded_polling
    raise e
  File "C:\Users\–¢–∏–º–∞\PycharmProjects\TelegramBot\venv\Lib\site-packages\telebot\__init__.py", line 1235, in __threaded_polling
    self.worker_pool.raise_exceptions()
    ~~~~~~~~~~~~~~~~~~~~~~~~~~~~~~~~~^^
  File "C:\Users\–¢–∏–º–∞\PycharmProjects\TelegramBot\venv\Lib\site-packages\telebot\util.py", line 150, in raise_exceptions
    raise self.exception_info
  File "C:\Users\–¢–∏–º–∞\PycharmProjects\TelegramBot\venv\Lib\site-packages\telebot\util.py", line 93, in run
    task(*args, **kwargs)
    ~~~~^^^^^^^^^^^^^^^^^
  File "C:\Users\–¢–∏–º–∞\PycharmProjects\TelegramBot\main.py", line 93, in change_settings_handler_2
    if TRANSLATE[msg.text] in settings[user_id].keys():
       ~~~~~~~~~^^^^^^^^^^
KeyError: '–ú–æ–¥–µ–ª—å –Ω–µ–π—Ä–æ—Å–µ—Ç–∏'

2025-01-31 19 - TeleBot - ERROR - Infinity polling: polling exited
2025-01-31 19 - TeleBot - ERROR - Break infinity polling
2025-01-31 19 - TeleBot - ERROR - Infinity polling: polling exited
2025-01-31 19 - TeleBot - ERROR - Break infinity polling
2025-01-31 19 - TeleBot - ERROR - Infinity polling: polling exited
2025-01-31 19 - TeleBot - ERROR - Break infinity polling
2025-01-31 19 - root - INFO - DATABASE: INSERT INTO messages VALUES (5948417394, –ü—Ä–∏–≤–µ—Ç, –∞ –∫–∞–∫ –Ω–∞–∑—ã–≤–∞–µ—Ç—Å—è —Ç–≤–æ—è –º–æ–¥–µ–ª—å?, user, 0)
2025-01-31 19 - root - INFO - DATABASE: INSERT INTO messages VALUES (5948417394, —Ç—ã gpt4o –∏–ª–∏ gpt4o mini?, user, 0)
2025-01-31 19 - TeleBot - ERROR - Infinity polling: polling exited
2025-01-31 19 - TeleBot - ERROR - Break infinity polling
2025-01-31 19 - TeleBot - ERROR - Infinity polling: polling exited
2025-01-31 19 - TeleBot - ERROR - Break infinity polling
2025-01-31 19 - TeleBot - ERROR - Infinity polling: polling exited
2025-01-31 19 - TeleBot - ERROR - Break infinity polling
2025-01-31 19 - TeleBot - ERROR - Infinity polling: polling exited
2025-01-31 19 - TeleBot - ERROR - Break infinity polling
2025-01-31 19 - TeleBot - ERROR - Infinity polling: polling exited
2025-01-31 19 - TeleBot - ERROR - Break infinity polling
2025-01-31 19 - TeleBot - ERROR - Infinity polling: polling exited
2025-01-31 19 - TeleBot - ERROR - Break infinity polling
2025-01-31 19 - TeleBot - ERROR - Infinity polling: polling exited
2025-01-31 19 - TeleBot - ERROR - Break infinity polling
2025-01-31 19 - TeleBot - ERROR - Infinity polling: polling exited
2025-01-31 19 - TeleBot - ERROR - Break infinity polling
2025-01-31 19 - TeleBot - ERROR - Infinity polling exception: 5948417394
2025-01-31 19 - TeleBot - ERROR - Exception traceback:
Traceback (most recent call last):
  File "C:\Users\–¢–∏–º–∞\PycharmProjects\TelegramBot\venv\Lib\site-packages\telebot\__init__.py", line 1110, in infinity_polling
    self.polling(non_stop=True, timeout=timeout, long_polling_timeout=long_polling_timeout,
    ~~~~~~~~~~~~^^^^^^^^^^^^^^^^^^^^^^^^^^^^^^^^^^^^^^^^^^^^^^^^^^^^^^^^^^^^^^^^^^^^^^^^^^^
                 logger_level=logger_level, allowed_updates=allowed_updates, restart_on_change=False,
                 ^^^^^^^^^^^^^^^^^^^^^^^^^^^^^^^^^^^^^^^^^^^^^^^^^^^^^^^^^^^^^^^^^^^^^^^^^^^^^^^^^^^^
                 *args, **kwargs)
                 ^^^^^^^^^^^^^^^^
  File "C:\Users\–¢–∏–º–∞\PycharmProjects\TelegramBot\venv\Lib\site-packages\telebot\__init__.py", line 1198, in polling
    self.__threaded_polling(non_stop=non_stop, interval=interval, timeout=timeout, long_polling_timeout=long_polling_timeout,
    ~~~~~~~~~~~~~~~~~~~~~~~^^^^^^^^^^^^^^^^^^^^^^^^^^^^^^^^^^^^^^^^^^^^^^^^^^^^^^^^^^^^^^^^^^^^^^^^^^^^^^^^^^^^^^^^^^^^^^^^^^
                            logger_level=logger_level, allowed_updates=allowed_updates)
                            ^^^^^^^^^^^^^^^^^^^^^^^^^^^^^^^^^^^^^^^^^^^^^^^^^^^^^^^^^^^
  File "C:\Users\–¢–∏–º–∞\PycharmProjects\TelegramBot\venv\Lib\site-packages\telebot\__init__.py", line 1273, in __threaded_polling
    raise e
  File "C:\Users\–¢–∏–º–∞\PycharmProjects\TelegramBot\venv\Lib\site-packages\telebot\__init__.py", line 1235, in __threaded_polling
    self.worker_pool.raise_exceptions()
    ~~~~~~~~~~~~~~~~~~~~~~~~~~~~~~~~~^^
  File "C:\Users\–¢–∏–º–∞\PycharmProjects\TelegramBot\venv\Lib\site-packages\telebot\util.py", line 150, in raise_exceptions
    raise self.exception_info
  File "C:\Users\–¢–∏–º–∞\PycharmProjects\TelegramBot\venv\Lib\site-packages\telebot\util.py", line 93, in run
    task(*args, **kwargs)
    ~~~~^^^^^^^^^^^^^^^^^
  File "C:\Users\–¢–∏–º–∞\PycharmProjects\TelegramBot\venv\Lib\site-packages\telebot\__init__.py", line 9233, in _run_middlewares_and_handler
    result = handler['function'](message)
  File "C:\Users\–¢–∏–º–∞\PycharmProjects\TelegramBot\main.py", line 72, in show_settings
    for k, v in settings[user_id].items():
                ~~~~~~~~^^^^^^^^^
KeyError: 5948417394

2025-01-31 19 - TeleBot - ERROR - Infinity polling: polling exited
2025-01-31 19 - TeleBot - ERROR - Break infinity polling
2025-01-31 19 - root - INFO - DATABASE: INSERT INTO messages VALUES (5948417394, –ß–µ –∫–∞–∫ –∂–∏—Ç—É—Ö–∞ –±—Ä–∞—Ç–∞–Ω, user, 0)
2025-01-31 19 - TeleBot - ERROR - Infinity polling: polling exited
2025-01-31 19 - TeleBot - ERROR - Break infinity polling
2025-01-31 19 - root - INFO - DATABASE: INSERT INTO messages VALUES (5948417394, –î–∞—Ä–æ–≤–∞ –∫–µ–Ω—Ç, user, 0)
2025-01-31 19 - TeleBot - ERROR - Infinity polling: polling exited
2025-01-31 19 - TeleBot - ERROR - Break infinity polling
2025-01-31 19 - root - INFO - DATABASE: INSERT INTO messages VALUES (5948417394, –≠–π –∫–µ–Ω—Ç–∏—à–∫–∞ —á—ã —á–æ—Ç–æ –Ω–µ –æ—Ç–≤–µ—á–∞–µ—à —è —Å–º–æ—Ç—Ä—é –¥–∞, user, 0)
2025-01-31 19 - TeleBot - ERROR - Infinity polling: polling exited
2025-01-31 19 - TeleBot - ERROR - Break infinity polling
2025-01-31 19 - root - INFO - DATABASE: INSERT INTO messages VALUES (5948417394, gpt-4o-mini, user, 0)
2025-01-31 19 - TeleBot - ERROR - Infinity polling: polling exited
2025-01-31 19 - TeleBot - ERROR - Break infinity polling
2025-01-31 19 - root - INFO - DATABASE: INSERT INTO messages VALUES (5948417394, —Ö–æ—á—É —Å —Ç–æ–±–æ–π –ø–µ—Ä–µ—Ç–µ—Ä–µ—Ç—å –≤–æ—Ç –æ —á–µ–º: —Å–∫–æ—Ä–æ –ø—Ä–æ–µ–∫—Ç —Å–¥–∞–≤–∞—Ç—å, –∞ –≤—Ä–µ–º–µ–Ω–∏ –Ω–æ–ª—å. –º–æ—Ç–∏–≤–∞—Ü–∏–∏ –Ω–µ—Ç, –ø–æ–Ω–∏–º–∞–µ—à—å?, user, 0)
2025-01-31 19 - root - INFO - DATABASE: INSERT INTO messages VALUES (5948417394, –π–æ—É –±—Ä–∞—Ç–∞–Ω, —Ç—ã —Ä–µ–∞–ª—å–Ω–æ –ø–æ–º–æ–≥. —É–≤–∞–∂–∞—é, user, 0)
2025-01-31 19 - root - INFO - DATABASE: INSERT INTO messages VALUES (5948417394, –∞ —Ç–≤–æ—è –∂–∏—Ç—É—Ö–∞ –∫–∞–∫? —Å–º–æ—Ç—Ä—é, –≥–æ–≤–æ—Ä–∏—à—å —Ç—ã –±–æ–¥—Ä–æ, user, 0)
2025-01-31 19 - TeleBot - ERROR - Infinity polling: polling exited
2025-01-31 19 - TeleBot - ERROR - Break infinity polling
2025-01-31 20 - root - INFO - DATABASE: INSERT INTO messages VALUES (5948417394, /lox, user, 0)
2025-01-31 20 - root - INFO - DATABASE: INSERT INTO messages VALUES (5948417394, /lox, user, 0)
2025-01-31 20 - root - INFO - DATABASE: INSERT INTO messages VALUES (5948417394, –†–∞–¥ –±—ã–ª –ø–æ–º–æ—á—å! –ï—Å–ª–∏ —É —Ç–µ–±—è –µ—Å—Ç—å –µ—â—ë –≤–æ–ø—Ä–æ—Å—ã –∏–ª–∏ –ø—Ä–æ—Å—Ç–æ —Ö–æ—á–µ—à—å –ø–æ–±–æ–ª—Ç–∞—Ç—å, –≤—Å–µ–≥–¥–∞ –Ω–∞ —Å–≤—è–∑–∏. üòä, assistant, 887)
2025-01-31 20 - root - INFO - DATABASE: INSERT INTO messages VALUES (5948417394, –ò–∑–≤–∏–Ω–∏—Ç–µ, —è –Ω–µ —Å–æ–≤—Å–µ–º –ø–æ–Ω—è–ª –≤–∞—à–µ —Å–æ–æ–±—â–µ–Ω–∏–µ. –ú–æ–≥–ª–∏ –±—ã –≤—ã —É—Ç–æ—á–Ω–∏—Ç—å?, assistant, 934)
2025-01-31 20 - TeleBot - ERROR - Infinity polling: polling exited
2025-01-31 20 - TeleBot - ERROR - Break infinity polling
2025-01-31 20 - root - INFO - DATABASE: 5948417394 –ø–æ—Ç—Ä–∞—Ç–∏–ª 2295 —Ç–æ–∫–µ–Ω–æ–≤
2025-01-31 20 - root - INFO - DATABASE: 5948417394 –ø–æ—Ç—Ä–∞—Ç–∏–ª 2295 —Ç–æ–∫–µ–Ω–æ–≤
2025-01-31 20 - root - INFO - DATABASE: INSERT INTO messages VALUES (5948417394, –ö–∞–∫ —Ç–≤–æ–∏ –¥–µ–ª–∞?, user, 0)
2025-01-31 20 - root - INFO - DATABASE: INSERT INTO messages VALUES (5948417394, –°–ø–∞—Å–∏–±–æ, —á—Ç–æ —Å–ø—Ä–æ—Å–∏–ª! –£ –º–µ–Ω—è –≤—Å—ë —Ö–æ—Ä–æ—à–æ. –ê –∫–∞–∫ —É —Ç–µ–±—è? –ß—Ç–æ –Ω–æ–≤–æ–≥–æ?, assistant, 98)
2025-01-31 20 - root - INFO - DATABASE: 5948417394 –ø–æ—Ç—Ä–∞—Ç–∏–ª 2393 —Ç–æ–∫–µ–Ω–æ–≤
2025-01-31 20 - root - INFO - DATABASE: 5948417394 –ø–æ—Ç—Ä–∞—Ç–∏–ª 2393 —Ç–æ–∫–µ–Ω–æ–≤
2025-01-31 20 - root - INFO - DATABASE: INSERT INTO messages VALUES (5948417394, —É –º–µ–Ω—è –≤—Å–µ —Ö–æ—Ä–æ—à–æ, –Ω–æ —è –Ω–µ –ø–æ–Ω–∏–º–∞—é —Å–∏–Ω—É—Å—ã. –ú–æ–∂–µ—à—å –æ–±—ä—è—Å–Ω–∏—Ç—å, —á—Ç–æ —ç—Ç–æ —Ç–∞–∫–æ–µ?, user, 0)
2025-01-31 20 - root - INFO - DATABASE: INSERT INTO messages VALUES (5948417394, –ö–æ–Ω–µ—á–Ω–æ! –°–∏–Ω—É—Å ‚Äî —ç—Ç–æ –æ–¥–Ω–∞ –∏–∑ –æ—Å–Ω–æ–≤–Ω—ã—Ö —Ç—Ä–∏–≥–æ–Ω–æ–º–µ—Ç—Ä–∏—á–µ—Å–∫–∏—Ö —Ñ—É–Ω–∫—Ü–∏–π. –í –ø—Ä–æ—Å—Ç—ã—Ö —Å–ª–æ–≤–∞—Ö, —Å–∏–Ω—É—Å –ø–æ–∑–≤–æ–ª—è–µ—Ç –Ω–∞–º –æ–ø—Ä–µ–¥–µ–ª–∏—Ç—å —Å–æ–æ—Ç–Ω–æ—à–µ–Ω–∏–µ –º–µ–∂–¥—É —Å—Ç–æ—Ä–æ–Ω–∞–º–∏ –ø—Ä—è–º–æ—É–≥–æ–ª—å–Ω–æ–≥–æ —Ç—Ä–µ—É–≥–æ–ª—å–Ω–∏–∫–∞.

–ï—Å–ª–∏ —É —Ç–µ–±—è –µ—Å—Ç—å –ø—Ä—è–º–æ—É–≥–æ–ª—å–Ω—ã–π —Ç—Ä–µ—É–≥–æ–ª—å–Ω–∏–∫, —Å–∏–Ω—É—Å —É–≥–ª–∞ (–æ–±—ã—á–Ω–æ –æ–±–æ–∑–Ω–∞—á–∞–µ–º–æ–≥–æ –±—É–∫–≤–æ–π "Œ±") —Ä–∞–≤–µ–Ω –æ—Ç–Ω–æ—à–µ–Ω–∏—é –¥–ª–∏–Ω—ã –ø—Ä–æ—Ç–∏–≤–æ–ª–µ–∂–∞—â–µ–π —Å—Ç–æ—Ä–æ–Ω—ã –∫ –¥–ª–∏–Ω–µ –≥–∏–ø–æ—Ç–µ–Ω—É–∑—ã (—Å–∞–º–æ–π –¥–ª–∏–Ω–Ω–æ–π —Å—Ç–æ—Ä–æ–Ω—ã —Ç—Ä–µ—É–≥–æ–ª—å–Ω–∏–∫–∞):

\[
\sin(Œ±) = \frac{\text{–¥–ª–∏–Ω–∞ –ø—Ä–æ—Ç–∏–≤–æ–ª–µ–∂–∞—â–µ–π —Å—Ç–æ—Ä–æ–Ω—ã}}{\text{–¥–ª–∏–Ω–∞ –≥–∏–ø–æ—Ç–µ–Ω—É–∑—ã}}
\]

–°–∏–Ω—É—Å –ø—Ä–∏–Ω–∏–º–∞–µ—Ç –∑–Ω–∞—á–µ–Ω–∏—è –æ—Ç -1 –¥–æ 1, –∏ –µ–≥–æ –ø–µ—Ä–∏–æ–¥ ‚Äî 360 –≥—Ä–∞–¥—É—Å–æ–≤ (–∏–ª–∏ 2œÄ —Ä–∞–¥–∏–∞–Ω–æ–≤), —á—Ç–æ –æ–∑–Ω–∞—á–∞–µ—Ç, —á—Ç–æ –∑–Ω–∞—á–µ–Ω–∏—è —Å–∏–Ω—É—Å–∞ –ø–æ–≤—Ç–æ—Ä—è—é—Ç—Å—è –∫–∞–∂–¥—ã–µ 360 –≥—Ä–∞–¥—É—Å–æ–≤.

–ï—Å–ª–∏ —Ç–µ–±–µ –Ω—É–∂–Ω—ã –±–æ–ª–µ–µ –∫–æ–Ω–∫—Ä–µ—Ç–Ω—ã–µ –ø—Ä–∏–º–µ—Ä—ã –∏–ª–∏ –æ–±—ä—è—Å–Ω–µ–Ω–∏—è, –¥–∞–π –∑–Ω–∞—Ç—å!, assistant, 275)
2025-01-31 20 - TeleBot - ERROR - Infinity polling: polling exited
2025-01-31 20 - TeleBot - ERROR - Break infinity polling
2025-01-31 20 - root - INFO - DATABASE: 5948417394 –ø–æ—Ç—Ä–∞—Ç–∏–ª 2668 —Ç–æ–∫–µ–Ω–æ–≤
2025-01-31 20 - root - INFO - DATABASE: 5948417394 –ø–æ—Ç—Ä–∞—Ç–∏–ª 2668 —Ç–æ–∫–µ–Ω–æ–≤
2025-01-31 20 - root - INFO - DATABASE: INSERT INTO messages VALUES (5948417394, –æ–ø–∏—à–∏ —Å–∏–Ω—Ç–∞–∫—Å–∏—Å LaTeX, user, 0)
2025-01-31 20 - root - INFO - DATABASE: 5948417394 –ø–æ—Ç—Ä–∞—Ç–∏–ª 2668 —Ç–æ–∫–µ–Ω–æ–≤
2025-01-31 20 - root - INFO - DATABASE: 5948417394 –ø–æ—Ç—Ä–∞—Ç–∏–ª 2668 —Ç–æ–∫–µ–Ω–æ–≤
2025-01-31 20 - root - INFO - DATABASE: INSERT INTO messages VALUES (5948417394, –æ–ø–∏—à–∏ —Å–∏–Ω—Ç–∞–∫—Å–∏—Å LaTeX, user, 0)
2025-01-31 20 - root - INFO - DATABASE: INSERT INTO messages VALUES (5948417394, LaTeX ‚Äî —ç—Ç–æ —Å–∏—Å—Ç–µ–º–∞ –ø–æ–¥–≥–æ—Ç–æ–≤–∫–∏ –¥–æ–∫—É–º–µ–Ω—Ç–æ–≤, —à–∏—Ä–æ–∫–æ –∏—Å–ø–æ–ª—å–∑—É–µ–º–∞—è –¥–ª—è —Å–æ–∑–¥–∞–Ω–∏—è –Ω–∞—É—á–Ω—ã—Ö –∏ —Ç–µ—Ö–Ω–∏—á–µ—Å–∫–∏—Ö —Ç–µ–∫—Å—Ç–æ–≤. –û–Ω –ø—Ä–µ–¥–æ—Å—Ç–∞–≤–ª—è–µ—Ç –º–æ—â–Ω—ã–µ –∏–Ω—Å—Ç—Ä—É–º–µ–Ω—Ç—ã –¥–ª—è –æ—Ñ–æ—Ä–º–ª–µ–Ω–∏—è, —É–ø—Ä–∞–≤–ª–µ–Ω–∏—è —Å—Å—ã–ª–∫–∞–º–∏ –∏ —Å–æ–∑–¥–∞–Ω–∏—è –º–∞—Ç–µ–º–∞—Ç–∏—á–µ—Å–∫–∏—Ö —Ñ–æ—Ä–º—É–ª. –í–æ—Ç –æ—Å–Ω–æ–≤–Ω—ã–µ —ç–ª–µ–º–µ–Ω—Ç—ã —Å–∏–Ω—Ç–∞–∫—Å–∏—Å–∞ LaTeX:

1. **–°—Ç—Ä—É–∫—Ç—É—Ä–∞ –¥–æ–∫—É–º–µ–Ω—Ç–∞**:
   –ö–∞–∂–¥—ã–π –¥–æ–∫—É–º–µ–Ω—Ç –≤ LaTeX –Ω–∞—á–∏–Ω–∞–µ—Ç—Å—è —Å —É–∫–∞–∑–∞–Ω–∏—è –∫–ª–∞—Å—Å–∞ –¥–æ–∫—É–º–µ–Ω—Ç–∞:
   ```latex
   \documentclass{article}
   ```

2. **–ü–∞–∫–µ—Ç—ã**:
   –ï—Å–ª–∏ –Ω—É–∂–Ω—ã –¥–æ–ø–æ–ª–Ω–∏—Ç–µ–ª—å–Ω—ã–µ —Ñ—É–Ω–∫—Ü–∏–∏, –∏—Ö –º–æ–∂–Ω–æ –ø–æ–¥–∫–ª—é—á–∏—Ç—å —Å –ø–æ–º–æ—â—å—é –∫–æ–º–∞–Ω–¥—ã `\usepackage`:
   ```latex
   \usepackage{amsmath} % –¥–ª—è –º–∞—Ç–µ–º–∞—Ç–∏—á–µ—Å–∫–∏—Ö —Ñ–æ—Ä–º—É–ª
   \usepackage{graphicx} % –¥–ª—è –≤—Å—Ç–∞–≤–∫–∏ –∏–∑–æ–±—Ä–∞–∂–µ–Ω–∏–π
   ```

3. **–ù–∞—á–∞–ª–æ –∏ –∫–æ–Ω–µ—Ü –¥–æ–∫—É–º–µ–Ω—Ç–∞**:
   –¢–µ–∫—Å—Ç –¥–æ–∫—É–º–µ–Ω—Ç–∞ –æ–ø—Ä–µ–¥–µ–ª—è–µ—Ç—Å—è –º–µ–∂–¥—É `\begin{document}` –∏ `\end{document}`:
   ```latex
   \begin{document}
   –¢–µ–∫—Å—Ç –≤–∞—à–µ–≥–æ –¥–æ–∫—É–º–µ–Ω—Ç–∞ –∑–¥–µ—Å—å.
   \end{document}
   ```

4. **–¢–µ–∫—Å—Ç–æ–≤—ã–µ –∫–æ–º–∞–Ω–¥—ã**:
   –ß—Ç–æ–±—ã –∏–∑–º–µ–Ω–∏—Ç—å —Å—Ç–∏–ª—å —Ç–µ–∫—Å—Ç–∞, –∏—Å–ø–æ–ª—å–∑—É—é—Ç—Å—è —Ä–∞–∑–ª–∏—á–Ω—ã–µ –∫–æ–º–∞–Ω–¥—ã:
   - **–ñ–∏—Ä–Ω—ã–π —à—Ä–∏—Ñ—Ç**: `\textbf{–∂–∏—Ä–Ω—ã–π —Ç–µ–∫—Å—Ç}`
   - **–ö—É—Ä—Å–∏–≤**: `\textit{–∫—É—Ä—Å–∏–≤–Ω—ã–π —Ç–µ–∫—Å—Ç}`
   - **–ü–æ–¥—á—ë—Ä–∫–Ω—É—Ç—ã–π —Ç–µ–∫—Å—Ç**: `\underline{–ø–æ–¥—á—ë—Ä–∫–Ω—É—Ç—ã–π —Ç–µ–∫—Å—Ç}`

5. **–°–ø–∏—Å–∫–∏**:
   –°–ø–∏—Å–∫–∏ –º–æ–∂–Ω–æ —Å–æ–∑–¥–∞–≤–∞—Ç—å —Å –ø–æ–º–æ—â—å—é –∫–æ–º–∞–Ω–¥ `itemize` –∏–ª–∏ `enumerate`:
   ```latex
   \begin{itemize}
       \item –ü–µ—Ä–≤—ã–π —ç–ª–µ–º–µ–Ω—Ç
       \item –í—Ç–æ—Ä–æ–π —ç–ª–µ–º–µ–Ω—Ç
   \end{itemize}

   \begin{enumerate}
       \item –ù—É–º–µ—Ä–æ–≤–∞–Ω–Ω—ã–π —ç–ª–µ–º–µ–Ω—Ç –æ–¥–∏–Ω
       \item –ù—É–º–µ—Ä–æ–≤–∞–Ω–Ω—ã–π —ç–ª–µ–º–µ–Ω—Ç –¥–≤–∞
   \end{enumerate}
   ```

6. **–ú–∞—Ç–µ–º–∞—Ç–∏—á–µ—Å–∫–∏–µ —Ñ–æ—Ä–º—É–ª—ã**:
   –ú–∞—Ç–µ–º–∞—Ç–∏–∫–∞ –ø–∏—à–µ—Ç—Å—è –º–µ–∂–¥—É –∑–Ω–∞–∫–∞–º–∏ `$...$` –¥–ª—è –≤—Å—Ç—Ä–æ–µ–Ω–Ω–æ–≥–æ —Ñ–æ—Ä–º–∞—Ç–∞ –∏–ª–∏ `\[...\]` –¥–ª—è –æ—Ç–¥–µ–ª—å–Ω–æ–π —Å—Ç—Ä–æ–∫–∏:
   ```latex
   –í—Å—Ç—Ä–æ–µ–Ω–Ω–∞—è —Ñ–æ—Ä–º–∞: $E=mc^2$.

   –û—Ç–¥–µ–ª—å–Ω–∞—è —Å—Ç—Ä–æ–∫–∞:
   \[
   E=mc^2
   \]
   ```

7. **–í—Å—Ç–∞–≤–∫–∞ –∏–∑–æ–±—Ä–∞–∂–µ–Ω–∏–π**:
   –î–ª—è –≤—Å—Ç–∞–≤–∫–∏ –∏–∑–æ–±—Ä–∞–∂–µ–Ω–∏–π –∏—Å–ø–æ–ª—å–∑—É–µ—Ç—Å—è –∫–æ–º–∞–Ω–¥–∞ `\includegraphics`:
   ```latex
   \begin{figure}
       \centering
       \includegraphics[width=0.5\textwidth]{image.png}
       \caption{–û–ø–∏—Å–∞–Ω–∏–µ –∏–∑–æ–±—Ä–∞–∂–µ–Ω–∏—è}
       \label{fig:sample}
   \end{figure}
   ```

8. **–°—Å—ã–ª–∫–∏ –∏ –±–∏–±–ª–∏–æ–≥—Ä–∞—Ñ–∏—è**:
   –ò—Å–ø–æ–ª—å–∑—É–π—Ç–µ –∫–æ–º–∞–Ω–¥—ã –¥–ª—è —Å–æ–∑–¥–∞–Ω–∏—è —Å—Å—ã–ª–æ–∫ –∏ –±–∏–±–ª–∏–æ–≥—Ä–∞—Ñ–∏–π:
   ```latex
   \cite{–∫–ª—é—á} –¥–ª—è —Å—Å—ã–ª–æ–∫ –Ω–∞ –±–∏–±–ª–∏–æ–≥—Ä–∞—Ñ–∏—é.
   ```

–≠—Ç–æ –ª–∏—à—å –æ—Å–Ω–æ–≤–Ω—ã–µ —ç–ª–µ–º–µ–Ω—Ç—ã —Å–∏–Ω—Ç–∞–∫—Å–∏—Å–∞ LaTeX. –ï—Å–ª–∏ –≤–∞—Å –∏–Ω—Ç–µ—Ä–µ—Å—É–µ—Ç —á—Ç–æ-—Ç–æ –∫–æ–Ω–∫—Ä–µ—Ç–Ω–æ–µ –∏–ª–∏ –≤—ã —Ö–æ—Ç–∏—Ç–µ –∑–Ω–∞—Ç—å –æ –±–æ–ª–µ–µ —Å–ª–æ–∂–Ω—ã—Ö –∞—Å–ø–µ–∫—Ç–∞—Ö, –¥–∞–π—Ç–µ –∑–Ω–∞—Ç—å!, assistant, 889)
2025-01-31 20 - root - INFO - DATABASE: INSERT INTO messages VALUES (5948417394, LaTeX ‚Äî —ç—Ç–æ —Å–∏—Å—Ç–µ–º–∞ –≤—ë—Ä—Å—Ç–∫–∏, –∏—Å–ø–æ–ª—å–∑—É–µ–º–∞—è –¥–ª—è —Å–æ–∑–¥–∞–Ω–∏—è –¥–æ–∫—É–º–µ–Ω—Ç–æ–≤, –æ—Å–æ–±–µ–Ω–Ω–æ —Ç–µ—Ö, –∫–æ—Ç–æ—Ä—ã–µ —Å–æ–¥–µ—Ä–∂–∞—Ç —Å–ª–æ–∂–Ω—ã–µ –º–∞—Ç–µ–º–∞—Ç–∏—á–µ—Å–∫–∏–µ —Ñ–æ—Ä–º—É–ª—ã. –û—Å–Ω–æ–≤–Ω–æ–π —Å–∏–Ω—Ç–∞–∫—Å–∏—Å LaTeX –≤–∫–ª—é—á–∞–µ—Ç –≤ —Å–µ–±—è –Ω–µ—Å–∫–æ–ª—å–∫–æ –∫–ª—é—á–µ–≤—ã—Ö –∫–æ–º–ø–æ–Ω–µ–Ω—Ç–æ–≤:

### 1. –û—Å–Ω–æ–≤–Ω–∞—è —Å—Ç—Ä—É–∫—Ç—É—Ä–∞ –¥–æ–∫—É–º–µ–Ω—Ç–∞
–ö–∞–∂–¥—ã–π –¥–æ–∫—É–º–µ–Ω—Ç –Ω–∞ LaTeX –Ω–∞—á–∏–Ω–∞–µ—Ç—Å—è —Å —É–∫–∞–∑–∞–Ω–∏—è –∫–ª–∞—Å—Å–∞ –¥–æ–∫—É–º–µ–Ω—Ç–∞ –∏ –≤–∫–ª—é—á–∞–µ—Ç –≤ —Å–µ–±—è –æ—Å–Ω–æ–≤–Ω—ã–µ —Å–µ–∫—Ü–∏–∏. –ü—Ä–æ—Å—Ç–æ–π –ø—Ä–∏–º–µ—Ä:

```latex
\documentclass{article}  % –£–∫–∞–∑—ã–≤–∞–µ—Ç –∫–ª–∞—Å—Å –¥–æ–∫—É–º–µ–Ω—Ç–∞ (–Ω–∞–ø—Ä–∏–º–µ—Ä, article, report, book)
\begin{document}         % –ù–∞—á–∞–ª–æ –¥–æ–∫—É–º–µ–Ω—Ç–∞
Hello, world!            % –û—Å–Ω–æ–≤–Ω–æ–π —Ç–µ–∫—Å—Ç
\end{document}           % –ö–æ–Ω–µ—Ü –¥–æ–∫—É–º–µ–Ω—Ç–∞
```

### 2. –§–æ—Ä–º–∞—Ç–∏—Ä–æ–≤–∞–Ω–∏–µ —Ç–µ–∫—Å—Ç–∞
- **–ñ–∏—Ä–Ω—ã–π —Ç–µ–∫—Å—Ç:** `\textbf{—ç—Ç–æ –∂–∏—Ä–Ω—ã–π —Ç–µ–∫—Å—Ç}`
- **–ö—É—Ä—Å–∏–≤:** `\textit{—ç—Ç–æ –∫—É—Ä—Å–∏–≤–Ω—ã–π —Ç–µ–∫—Å—Ç}`
- **–ü–æ–¥—á—ë—Ä–∫–Ω—É—Ç—ã–π —Ç–µ–∫—Å—Ç:** `\underline{—ç—Ç–æ –ø–æ–¥—á—ë—Ä–∫–Ω—É—Ç—ã–π —Ç–µ–∫—Å—Ç}`

### 3. –ó–∞–≥–æ–ª–æ–≤–∫–∏ –∏ —Ä–∞–∑–¥–µ–ª—ã
LaTeX –ø–æ–∑–≤–æ–ª—è–µ—Ç —Å–æ–∑–¥–∞–≤–∞—Ç—å —Ä–∞–∑–¥–µ–ª—ã –∏ –ø–æ–¥—Ä–∞–∑–¥–µ–ª—ã:

```latex
\section{–ó–∞–≥–æ–ª–æ–≤–æ–∫ –ø–µ—Ä–≤–æ–≥–æ —É—Ä–æ–≤–Ω—è}
\subsection{–ó–∞–≥–æ–ª–æ–≤–æ–∫ –≤—Ç–æ—Ä–æ–≥–æ —É—Ä–æ–≤–Ω—è}
\subsubsection{–ó–∞–≥–æ–ª–æ–≤–æ–∫ —Ç—Ä–µ—Ç—å–µ–≥–æ —É—Ä–æ–≤–Ω—è}
```

### 4. –°–ø–∏—Å–∫–∏
- **–ù—É–º–µ—Ä–æ–≤–∞–Ω–Ω—ã–π —Å–ø–∏—Å–æ–∫:**
```latex
\begin{enumerate}
  \item –ü–µ—Ä–≤—ã–π –ø—É–Ω–∫—Ç
  \item –í—Ç–æ—Ä–æ–π –ø—É–Ω–∫—Ç
\end{enumerate}
```
- **–ú–∞—Ä–∫–∏—Ä–æ–≤–∞–Ω–Ω—ã–π —Å–ø–∏—Å–æ–∫:**
```latex
\begin{itemize}
  \item –ü–µ—Ä–≤—ã–π –ø—É–Ω–∫—Ç
  \item –í—Ç–æ—Ä–æ–π –ø—É–Ω–∫—Ç
\end{itemize}
```

### 5. –ú–∞—Ç–µ–º–∞—Ç–∏—á–µ—Å–∫–∏–µ —Ñ–æ—Ä–º—É–ª—ã
–î–ª—è –≤–∫–ª—é—á–µ–Ω–∏—è –º–∞—Ç–µ–º–∞—Ç–∏—á–µ—Å–∫–æ–≥–æ —Ç–µ–∫—Å—Ç–∞ –∏—Å–ø–æ–ª—å–∑—É—é—Ç—Å—è $...$ –¥–ª—è –≤—Å—Ç—Ä–æ–µ–Ω–Ω—ã—Ö —Ñ–æ—Ä–º—É–ª –∏ \[...\] –¥–ª—è –æ—Ç–¥–µ–ª—ë–Ω–Ω—ã—Ö:

```latex
–î–ª—è –≤—Å—Ç—Ä–æ–µ–Ω–Ω–æ–π —Ñ–æ—Ä–º—É–ª—ã: \( E = mc^2 \)

–î–ª—è –æ—Ç–¥–µ–ª—ë–Ω–Ω–æ–π —Ñ–æ—Ä–º—É–ª—ã:
\[
a^2 + b^2 = c^2
\]
```

### 6. –í—Å—Ç–∞–≤–∫–∞ –∏–∑–æ–±—Ä–∞–∂–µ–Ω–∏–π
–ß—Ç–æ–±—ã –≤—Å—Ç–∞–≤–∏—Ç—å –∏–∑–æ–±—Ä–∞–∂–µ–Ω–∏–µ, –∏—Å–ø–æ–ª—å–∑—É–π—Ç–µ –ø–∞–∫–µ—Ç `graphicx`:

```latex
\usepackage{graphicx}  % –í –ø—Ä–µ–∞–º–±—É–ª–µ
```

–í—Å—Ç–∞–≤–∫–∞ –∏–∑–æ–±—Ä–∞–∂–µ–Ω–∏—è:

```latex
\begin{figure}
  \centering
  \includegraphics[width=0.5\textwidth]{image.png}  % –£–∫–∞–∂–∏—Ç–µ –∏–º—è —Ñ–∞–π–ª–∞ –∏–∑–æ–±—Ä–∞–∂–µ–Ω–∏—è
  \caption{–≠—Ç–æ –ø–æ–¥–ø–∏—Å—å –∫ –∏–∑–æ–±—Ä–∞–∂–µ–Ω–∏—é}
\end{figure}
```

### 7. –°—Å—ã–ª–∫–∏ –∏ —Ü–∏—Ç–∞—Ç—ã
–î–ª—è —Å–æ–∑–¥–∞–Ω–∏—è —Å—Å—ã–ª–æ–∫ –∏—Å–ø–æ–ª—å–∑—É–π—Ç–µ –ø–∞–∫–µ—Ç `hyperref`:

```latex
\usepackage{hyperref}  % –í –ø—Ä–µ–∞–º–±—É–ª–µ
```

–°–æ–∑–¥–∞–Ω–∏–µ —Å—Å—ã–ª–∫–∏:

```latex
–≠—Ç–æ —Å—Å—ã–ª–∫–∞ –Ω–∞ \href{http://example.com}{Example Website}.
```

### 8. –ë–∏–±–ª–∏–æ–≥—Ä–∞—Ñ–∏—è
–î–ª—è –±–∏–±–ª–∏–æ–≥—Ä–∞—Ñ–∏–π –∏ —Ü–∏—Ç–∞—Ç –∏—Å–ø–æ–ª—å–∑—É–µ—Ç—Å—è –ø–∞–∫–µ—Ç `biblatex` –∏–ª–∏ `natbib`.

```latex
\usepackage{biblatex}  % –í –ø—Ä–µ–∞–º–±—É–ª–µ
\addbibresource{sources.bib}  % –ü–æ–¥–∫–ª—é—á–µ–Ω–∏–µ —Ñ–∞–π–ª–∞ —Å –±–∏–±–ª–∏–æ–≥—Ä–∞—Ñ–∏–µ–π

–¶–∏—Ç–∏—Ä—É–µ–º—ã–π —Ç–µ–∫—Å—Ç \cite{–∫–ª—é—á_—Ü–∏—Ç–∞—Ç—ã}.

\printbibliography  % –í—Å—Ç–∞–≤–∫–∞ —Å–ø–∏—Å–∫–∞ –ª–∏—Ç–µ—Ä–∞—Ç—É—Ä—ã
```

–≠—Ç–æ –±–∞–∑–æ–≤—ã–µ —ç–ª–µ–º–µ–Ω—Ç—ã —Å–∏–Ω—Ç–∞–∫—Å–∏—Å–∞ LaTeX. –°—É—â–µ—Å—Ç–≤—É–µ—Ç –º–Ω–æ–∂–µ—Å—Ç–≤–æ –¥–æ–ø–æ–ª–Ω–∏—Ç–µ–ª—å–Ω—ã—Ö –≤–æ–∑–º–æ–∂–Ω–æ—Å—Ç–µ–π –∏ –ø–∞–∫–µ—Ç–æ–≤, –∫–æ—Ç–æ—Ä—ã–µ –º–æ–≥—É—Ç –∑–Ω–∞—á–∏—Ç–µ–ª—å–Ω–æ —Ä–∞—Å—à–∏—Ä–∏—Ç—å —Ñ—É–Ω–∫—Ü–∏–æ–Ω–∞–ª—å–Ω–æ—Å—Ç—å LaTeX, –Ω–æ —ç—Ç–∏ –æ—Å–Ω–æ–≤–Ω—ã–µ –∫–æ–Ω—Å—Ç—Ä—É–∫—Ü–∏–∏ –ø–æ–º–æ–≥—É—Ç –Ω–∞—á–∞—Ç—å. –ï—Å–ª–∏ –µ—Å—Ç—å –∫–æ–Ω–∫—Ä–µ—Ç–Ω—ã–µ –≤–æ–ø—Ä–æ—Å—ã –∏–ª–∏ –ø–æ–∂–µ–ª–∞–Ω–∏—è, –Ω–µ —Å—Ç–µ—Å–Ω—è–π—Å—è —Å–ø—Ä–∞—à–∏–≤–∞—Ç—å!, assistant, 995)
2025-01-31 20 - TeleBot - ERROR - Infinity polling: polling exited
2025-01-31 20 - TeleBot - ERROR - Break infinity polling
2025-02-03 15 - root - INFO - DATABASE: 5948417394 –ø–æ—Ç—Ä–∞—Ç–∏–ª 10000 —Ç–æ–∫–µ–Ω–æ–≤
2025-02-03 15 - root - INFO - DATABASE: 5948417394 –ø–æ—Ç—Ä–∞—Ç–∏–ª 10000 —Ç–æ–∫–µ–Ω–æ–≤
2025-02-03 15 - TeleBot - ERROR - Threaded polling exception: A request to the Telegram API was unsuccessful. Error code: 400. Description: Bad Request: message text is empty
2025-02-03 15 - TeleBot - ERROR - Exception traceback:
Traceback (most recent call last):
  File "C:\Users\–¢–∏–º–∞\PycharmProjects\TelegramBot\venv\Lib\site-packages\telebot\__init__.py", line 1235, in __threaded_polling
    self.worker_pool.raise_exceptions()
    ~~~~~~~~~~~~~~~~~~~~~~~~~~~~~~~~~^^
  File "C:\Users\–¢–∏–º–∞\PycharmProjects\TelegramBot\venv\Lib\site-packages\telebot\util.py", line 150, in raise_exceptions
    raise self.exception_info
  File "C:\Users\–¢–∏–º–∞\PycharmProjects\TelegramBot\venv\Lib\site-packages\telebot\util.py", line 93, in run
    task(*args, **kwargs)
    ~~~~^^^^^^^^^^^^^^^^^
  File "C:\Users\–¢–∏–º–∞\PycharmProjects\TelegramBot\venv\Lib\site-packages\telebot\__init__.py", line 9233, in _run_middlewares_and_handler
    result = handler['function'](message)
  File "C:\Users\–¢–∏–º–∞\PycharmProjects\TelegramBot\main.py", line 136, in handle_text
    bot.send_message(user_id, '')
    ~~~~~~~~~~~~~~~~^^^^^^^^^^^^^
  File "C:\Users\–¢–∏–º–∞\PycharmProjects\TelegramBot\venv\Lib\site-packages\telebot\__init__.py", line 1800, in send_message
    apihelper.send_message(
    ~~~~~~~~~~~~~~~~~~~~~~^
        self.token, chat_id, text,
        ^^^^^^^^^^^^^^^^^^^^^^^^^^
    ...<2 lines>...
        reply_parameters=reply_parameters, link_preview_options=link_preview_options, business_connection_id=business_connection_id,
        ^^^^^^^^^^^^^^^^^^^^^^^^^^^^^^^^^^^^^^^^^^^^^^^^^^^^^^^^^^^^^^^^^^^^^^^^^^^^^^^^^^^^^^^^^^^^^^^^^^^^^^^^^^^^^^^^^^^^^^^^^^^^
        message_effect_id=message_effect_id, allow_paid_broadcast=allow_paid_broadcast))
        ^^^^^^^^^^^^^^^^^^^^^^^^^^^^^^^^^^^^^^^^^^^^^^^^^^^^^^^^^^^^^^^^^^^^^^^^^^^^^^^
  File "C:\Users\–¢–∏–º–∞\PycharmProjects\TelegramBot\venv\Lib\site-packages\telebot\apihelper.py", line 275, in send_message
    return _make_request(token, method_url, params=payload, method='post')
  File "C:\Users\–¢–∏–º–∞\PycharmProjects\TelegramBot\venv\Lib\site-packages\telebot\apihelper.py", line 168, in _make_request
    json_result = _check_result(method_name, result)
  File "C:\Users\–¢–∏–º–∞\PycharmProjects\TelegramBot\venv\Lib\site-packages\telebot\apihelper.py", line 195, in _check_result
    raise ApiTelegramException(method_name, result, result_json)
telebot.apihelper.ApiTelegramException: A request to the Telegram API was unsuccessful. Error code: 400. Description: Bad Request: message text is empty

2025-02-03 15 - TeleBot - ERROR - Infinity polling: polling exited
2025-02-03 15 - TeleBot - ERROR - Break infinity polling
2025-02-03 15 - root - INFO - DATABASE: 5948417394 –ø–æ—Ç—Ä–∞—Ç–∏–ª 10000 —Ç–æ–∫–µ–Ω–æ–≤
2025-02-03 15 - TeleBot - ERROR - Infinity polling exception: HTTPSConnectionPool(host='api.telegram.org', port=443): Read timed out. (read timeout=25)
2025-02-03 15 - TeleBot - ERROR - Exception traceback:
Traceback (most recent call last):
  File "C:\Users\–¢–∏–º–∞\PycharmProjects\TelegramBot\venv\Lib\site-packages\urllib3\connectionpool.py", line 534, in _make_request
    response = conn.getresponse()
  File "C:\Users\–¢–∏–º–∞\PycharmProjects\TelegramBot\venv\Lib\site-packages\urllib3\connection.py", line 516, in getresponse
    httplib_response = super().getresponse()
  File "C:\Program Files\Python313\Lib\http\client.py", line 1428, in getresponse
    response.begin()
    ~~~~~~~~~~~~~~^^
  File "C:\Program Files\Python313\Lib\http\client.py", line 331, in begin
    version, status, reason = self._read_status()
                              ~~~~~~~~~~~~~~~~~^^
  File "C:\Program Files\Python313\Lib\http\client.py", line 292, in _read_status
    line = str(self.fp.readline(_MAXLINE + 1), "iso-8859-1")
               ~~~~~~~~~~~~~~~~^^^^^^^^^^^^^^
  File "C:\Program Files\Python313\Lib\socket.py", line 719, in readinto
    return self._sock.recv_into(b)
           ~~~~~~~~~~~~~~~~~~~~^^^
  File "C:\Program Files\Python313\Lib\ssl.py", line 1304, in recv_into
    return self.read(nbytes, buffer)
           ~~~~~~~~~^^^^^^^^^^^^^^^^
  File "C:\Program Files\Python313\Lib\ssl.py", line 1138, in read
    return self._sslobj.read(len, buffer)
           ~~~~~~~~~~~~~~~~~^^^^^^^^^^^^^
TimeoutError: The read operation timed out

The above exception was the direct cause of the following exception:

Traceback (most recent call last):
  File "C:\Users\–¢–∏–º–∞\PycharmProjects\TelegramBot\venv\Lib\site-packages\requests\adapters.py", line 667, in send
    resp = conn.urlopen(
        method=request.method,
    ...<9 lines>...
        chunked=chunked,
    )
  File "C:\Users\–¢–∏–º–∞\PycharmProjects\TelegramBot\venv\Lib\site-packages\urllib3\connectionpool.py", line 841, in urlopen
    retries = retries.increment(
        method, url, error=new_e, _pool=self, _stacktrace=sys.exc_info()[2]
    )
  File "C:\Users\–¢–∏–º–∞\PycharmProjects\TelegramBot\venv\Lib\site-packages\urllib3\util\retry.py", line 474, in increment
    raise reraise(type(error), error, _stacktrace)
          ~~~~~~~^^^^^^^^^^^^^^^^^^^^^^^^^^^^^^^^^
  File "C:\Users\–¢–∏–º–∞\PycharmProjects\TelegramBot\venv\Lib\site-packages\urllib3\util\util.py", line 39, in reraise
    raise value
  File "C:\Users\–¢–∏–º–∞\PycharmProjects\TelegramBot\venv\Lib\site-packages\urllib3\connectionpool.py", line 787, in urlopen
    response = self._make_request(
        conn,
    ...<10 lines>...
        **response_kw,
    )
  File "C:\Users\–¢–∏–º–∞\PycharmProjects\TelegramBot\venv\Lib\site-packages\urllib3\connectionpool.py", line 536, in _make_request
    self._raise_timeout(err=e, url=url, timeout_value=read_timeout)
    ~~~~~~~~~~~~~~~~~~~^^^^^^^^^^^^^^^^^^^^^^^^^^^^^^^^^^^^^^^^^^^^
  File "C:\Users\–¢–∏–º–∞\PycharmProjects\TelegramBot\venv\Lib\site-packages\urllib3\connectionpool.py", line 367, in _raise_timeout
    raise ReadTimeoutError(
        self, url, f"Read timed out. (read timeout={timeout_value})"
    ) from err
urllib3.exceptions.ReadTimeoutError: HTTPSConnectionPool(host='api.telegram.org', port=443): Read timed out. (read timeout=25)

During handling of the above exception, another exception occurred:

Traceback (most recent call last):
  File "C:\Users\–¢–∏–º–∞\PycharmProjects\TelegramBot\venv\Lib\site-packages\telebot\__init__.py", line 1110, in infinity_polling
    self.polling(non_stop=True, timeout=timeout, long_polling_timeout=long_polling_timeout,
    ~~~~~~~~~~~~^^^^^^^^^^^^^^^^^^^^^^^^^^^^^^^^^^^^^^^^^^^^^^^^^^^^^^^^^^^^^^^^^^^^^^^^^^^
                 logger_level=logger_level, allowed_updates=allowed_updates, restart_on_change=False,
                 ^^^^^^^^^^^^^^^^^^^^^^^^^^^^^^^^^^^^^^^^^^^^^^^^^^^^^^^^^^^^^^^^^^^^^^^^^^^^^^^^^^^^
                 *args, **kwargs)
                 ^^^^^^^^^^^^^^^^
  File "C:\Users\–¢–∏–º–∞\PycharmProjects\TelegramBot\venv\Lib\site-packages\telebot\__init__.py", line 1198, in polling
    self.__threaded_polling(non_stop=non_stop, interval=interval, timeout=timeout, long_polling_timeout=long_polling_timeout,
    ~~~~~~~~~~~~~~~~~~~~~~~^^^^^^^^^^^^^^^^^^^^^^^^^^^^^^^^^^^^^^^^^^^^^^^^^^^^^^^^^^^^^^^^^^^^^^^^^^^^^^^^^^^^^^^^^^^^^^^^^^
                            logger_level=logger_level, allowed_updates=allowed_updates)
                            ^^^^^^^^^^^^^^^^^^^^^^^^^^^^^^^^^^^^^^^^^^^^^^^^^^^^^^^^^^^
  File "C:\Users\–¢–∏–º–∞\PycharmProjects\TelegramBot\venv\Lib\site-packages\telebot\__init__.py", line 1273, in __threaded_polling
    raise e
  File "C:\Users\–¢–∏–º–∞\PycharmProjects\TelegramBot\venv\Lib\site-packages\telebot\__init__.py", line 1234, in __threaded_polling
    polling_thread.raise_exceptions()
    ~~~~~~~~~~~~~~~~~~~~~~~~~~~~~~~^^
  File "C:\Users\–¢–∏–º–∞\PycharmProjects\TelegramBot\venv\Lib\site-packages\telebot\util.py", line 111, in raise_exceptions
    raise self.exception_info
  File "C:\Users\–¢–∏–º–∞\PycharmProjects\TelegramBot\venv\Lib\site-packages\telebot\util.py", line 93, in run
    task(*args, **kwargs)
    ~~~~^^^^^^^^^^^^^^^^^
  File "C:\Users\–¢–∏–º–∞\PycharmProjects\TelegramBot\venv\Lib\site-packages\telebot\__init__.py", line 688, in __retrieve_updates
    updates = self.get_updates(offset=(self.last_update_id + 1),
                               allowed_updates=allowed_updates,
                               timeout=timeout, long_polling_timeout=long_polling_timeout)
  File "C:\Users\–¢–∏–º–∞\PycharmProjects\TelegramBot\venv\Lib\site-packages\telebot\__init__.py", line 660, in get_updates
    json_updates = apihelper.get_updates(
        self.token, offset=offset, limit=limit, timeout=timeout, allowed_updates=allowed_updates,
        long_polling_timeout=long_polling_timeout)
  File "C:\Users\–¢–∏–º–∞\PycharmProjects\TelegramBot\venv\Lib\site-packages\telebot\apihelper.py", line 332, in get_updates
    return _make_request(token, method_url, params=payload)
  File "C:\Users\–¢–∏–º–∞\PycharmProjects\TelegramBot\venv\Lib\site-packages\telebot\apihelper.py", line 162, in _make_request
    result = _get_req_session().request(
        method, request_url, params=params, files=files,
        timeout=(connect_timeout, read_timeout), proxies=proxy)
  File "C:\Users\–¢–∏–º–∞\PycharmProjects\TelegramBot\venv\Lib\site-packages\requests\sessions.py", line 589, in request
    resp = self.send(prep, **send_kwargs)
  File "C:\Users\–¢–∏–º–∞\PycharmProjects\TelegramBot\venv\Lib\site-packages\requests\sessions.py", line 703, in send
    r = adapter.send(request, **kwargs)
  File "C:\Users\–¢–∏–º–∞\PycharmProjects\TelegramBot\venv\Lib\site-packages\requests\adapters.py", line 713, in send
    raise ReadTimeout(e, request=request)
requests.exceptions.ReadTimeout: HTTPSConnectionPool(host='api.telegram.org', port=443): Read timed out. (read timeout=25)

2025-02-03 15 - TeleBot - ERROR - Infinity polling exception: HTTPSConnectionPool(host='api.telegram.org', port=443): Max retries exceeded with url: /bot7221935484:***********************************/getUpdates?offset=901297587&timeout=20 (Caused by NameResolutionError("<urllib3.connection.HTTPSConnection object at 0x000002C37038F750>: Failed to resolve 'api.telegram.org' ([Errno 11001] getaddrinfo failed)"))
2025-02-03 15 - TeleBot - ERROR - Exception traceback:
Traceback (most recent call last):
  File "C:\Users\–¢–∏–º–∞\PycharmProjects\TelegramBot\venv\Lib\site-packages\urllib3\connection.py", line 198, in _new_conn
    sock = connection.create_connection(
        (self._dns_host, self.port),
    ...<2 lines>...
        socket_options=self.socket_options,
    )
  File "C:\Users\–¢–∏–º–∞\PycharmProjects\TelegramBot\venv\Lib\site-packages\urllib3\util\connection.py", line 60, in create_connection
    for res in socket.getaddrinfo(host, port, family, socket.SOCK_STREAM):
               ~~~~~~~~~~~~~~~~~~^^^^^^^^^^^^^^^^^^^^^^^^^^^^^^^^^^^^^^^^
  File "C:\Program Files\Python313\Lib\socket.py", line 975, in getaddrinfo
    for res in _socket.getaddrinfo(host, port, family, type, proto, flags):
               ~~~~~~~~~~~~~~~~~~~^^^^^^^^^^^^^^^^^^^^^^^^^^^^^^^^^^^^^^^^
socket.gaierror: [Errno 11001] getaddrinfo failed

The above exception was the direct cause of the following exception:

Traceback (most recent call last):
  File "C:\Users\–¢–∏–º–∞\PycharmProjects\TelegramBot\venv\Lib\site-packages\urllib3\connectionpool.py", line 787, in urlopen
    response = self._make_request(
        conn,
    ...<10 lines>...
        **response_kw,
    )
  File "C:\Users\–¢–∏–º–∞\PycharmProjects\TelegramBot\venv\Lib\site-packages\urllib3\connectionpool.py", line 488, in _make_request
    raise new_e
  File "C:\Users\–¢–∏–º–∞\PycharmProjects\TelegramBot\venv\Lib\site-packages\urllib3\connectionpool.py", line 464, in _make_request
    self._validate_conn(conn)
    ~~~~~~~~~~~~~~~~~~~^^^^^^
  File "C:\Users\–¢–∏–º–∞\PycharmProjects\TelegramBot\venv\Lib\site-packages\urllib3\connectionpool.py", line 1093, in _validate_conn
    conn.connect()
    ~~~~~~~~~~~~^^
  File "C:\Users\–¢–∏–º–∞\PycharmProjects\TelegramBot\venv\Lib\site-packages\urllib3\connection.py", line 704, in connect
    self.sock = sock = self._new_conn()
                       ~~~~~~~~~~~~~~^^
  File "C:\Users\–¢–∏–º–∞\PycharmProjects\TelegramBot\venv\Lib\site-packages\urllib3\connection.py", line 205, in _new_conn
    raise NameResolutionError(self.host, self, e) from e
urllib3.exceptions.NameResolutionError: <urllib3.connection.HTTPSConnection object at 0x000002C37038F750>: Failed to resolve 'api.telegram.org' ([Errno 11001] getaddrinfo failed)

The above exception was the direct cause of the following exception:

Traceback (most recent call last):
  File "C:\Users\–¢–∏–º–∞\PycharmProjects\TelegramBot\venv\Lib\site-packages\requests\adapters.py", line 667, in send
    resp = conn.urlopen(
        method=request.method,
    ...<9 lines>...
        chunked=chunked,
    )
  File "C:\Users\–¢–∏–º–∞\PycharmProjects\TelegramBot\venv\Lib\site-packages\urllib3\connectionpool.py", line 841, in urlopen
    retries = retries.increment(
        method, url, error=new_e, _pool=self, _stacktrace=sys.exc_info()[2]
    )
  File "C:\Users\–¢–∏–º–∞\PycharmProjects\TelegramBot\venv\Lib\site-packages\urllib3\util\retry.py", line 519, in increment
    raise MaxRetryError(_pool, url, reason) from reason  # type: ignore[arg-type]
    ^^^^^^^^^^^^^^^^^^^^^^^^^^^^^^^^^^^^^^^^^^^^^^^^^^^
urllib3.exceptions.MaxRetryError: HTTPSConnectionPool(host='api.telegram.org', port=443): Max retries exceeded with url: /bot7221935484:***********************************/getUpdates?offset=901297587&timeout=20 (Caused by NameResolutionError("<urllib3.connection.HTTPSConnection object at 0x000002C37038F750>: Failed to resolve 'api.telegram.org' ([Errno 11001] getaddrinfo failed)"))

During handling of the above exception, another exception occurred:

Traceback (most recent call last):
  File "C:\Users\–¢–∏–º–∞\PycharmProjects\TelegramBot\venv\Lib\site-packages\telebot\__init__.py", line 1110, in infinity_polling
    self.polling(non_stop=True, timeout=timeout, long_polling_timeout=long_polling_timeout,
    ~~~~~~~~~~~~^^^^^^^^^^^^^^^^^^^^^^^^^^^^^^^^^^^^^^^^^^^^^^^^^^^^^^^^^^^^^^^^^^^^^^^^^^^
                 logger_level=logger_level, allowed_updates=allowed_updates, restart_on_change=False,
                 ^^^^^^^^^^^^^^^^^^^^^^^^^^^^^^^^^^^^^^^^^^^^^^^^^^^^^^^^^^^^^^^^^^^^^^^^^^^^^^^^^^^^
                 *args, **kwargs)
                 ^^^^^^^^^^^^^^^^
  File "C:\Users\–¢–∏–º–∞\PycharmProjects\TelegramBot\venv\Lib\site-packages\telebot\__init__.py", line 1198, in polling
    self.__threaded_polling(non_stop=non_stop, interval=interval, timeout=timeout, long_polling_timeout=long_polling_timeout,
    ~~~~~~~~~~~~~~~~~~~~~~~^^^^^^^^^^^^^^^^^^^^^^^^^^^^^^^^^^^^^^^^^^^^^^^^^^^^^^^^^^^^^^^^^^^^^^^^^^^^^^^^^^^^^^^^^^^^^^^^^^
                            logger_level=logger_level, allowed_updates=allowed_updates)
                            ^^^^^^^^^^^^^^^^^^^^^^^^^^^^^^^^^^^^^^^^^^^^^^^^^^^^^^^^^^^
  File "C:\Users\–¢–∏–º–∞\PycharmProjects\TelegramBot\venv\Lib\site-packages\telebot\__init__.py", line 1273, in __threaded_polling
    raise e
  File "C:\Users\–¢–∏–º–∞\PycharmProjects\TelegramBot\venv\Lib\site-packages\telebot\__init__.py", line 1234, in __threaded_polling
    polling_thread.raise_exceptions()
    ~~~~~~~~~~~~~~~~~~~~~~~~~~~~~~~^^
  File "C:\Users\–¢–∏–º–∞\PycharmProjects\TelegramBot\venv\Lib\site-packages\telebot\util.py", line 111, in raise_exceptions
    raise self.exception_info
  File "C:\Users\–¢–∏–º–∞\PycharmProjects\TelegramBot\venv\Lib\site-packages\telebot\util.py", line 93, in run
    task(*args, **kwargs)
    ~~~~^^^^^^^^^^^^^^^^^
  File "C:\Users\–¢–∏–º–∞\PycharmProjects\TelegramBot\venv\Lib\site-packages\telebot\__init__.py", line 688, in __retrieve_updates
    updates = self.get_updates(offset=(self.last_update_id + 1),
                               allowed_updates=allowed_updates,
                               timeout=timeout, long_polling_timeout=long_polling_timeout)
  File "C:\Users\–¢–∏–º–∞\PycharmProjects\TelegramBot\venv\Lib\site-packages\telebot\__init__.py", line 660, in get_updates
    json_updates = apihelper.get_updates(
        self.token, offset=offset, limit=limit, timeout=timeout, allowed_updates=allowed_updates,
        long_polling_timeout=long_polling_timeout)
  File "C:\Users\–¢–∏–º–∞\PycharmProjects\TelegramBot\venv\Lib\site-packages\telebot\apihelper.py", line 332, in get_updates
    return _make_request(token, method_url, params=payload)
  File "C:\Users\–¢–∏–º–∞\PycharmProjects\TelegramBot\venv\Lib\site-packages\telebot\apihelper.py", line 162, in _make_request
    result = _get_req_session().request(
        method, request_url, params=params, files=files,
        timeout=(connect_timeout, read_timeout), proxies=proxy)
  File "C:\Users\–¢–∏–º–∞\PycharmProjects\TelegramBot\venv\Lib\site-packages\requests\sessions.py", line 589, in request
    resp = self.send(prep, **send_kwargs)
  File "C:\Users\–¢–∏–º–∞\PycharmProjects\TelegramBot\venv\Lib\site-packages\requests\sessions.py", line 703, in send
    r = adapter.send(request, **kwargs)
  File "C:\Users\–¢–∏–º–∞\PycharmProjects\TelegramBot\venv\Lib\site-packages\requests\adapters.py", line 700, in send
    raise ConnectionError(e, request=request)
requests.exceptions.ConnectionError: HTTPSConnectionPool(host='api.telegram.org', port=443): Max retries exceeded with url: /bot7221935484:***********************************/getUpdates?offset=901297587&timeout=20 (Caused by NameResolutionError("<urllib3.connection.HTTPSConnection object at 0x000002C37038F750>: Failed to resolve 'api.telegram.org' ([Errno 11001] getaddrinfo failed)"))

2025-02-03 15 - TeleBot - ERROR - Infinity polling exception: HTTPSConnectionPool(host='api.telegram.org', port=443): Max retries exceeded with url: /bot7221935484:***********************************/getUpdates?offset=901297587&timeout=20 (Caused by NameResolutionError("<urllib3.connection.HTTPSConnection object at 0x000002C37038FED0>: Failed to resolve 'api.telegram.org' ([Errno 11001] getaddrinfo failed)"))
2025-02-03 15 - TeleBot - ERROR - Exception traceback:
Traceback (most recent call last):
  File "C:\Users\–¢–∏–º–∞\PycharmProjects\TelegramBot\venv\Lib\site-packages\urllib3\connection.py", line 198, in _new_conn
    sock = connection.create_connection(
        (self._dns_host, self.port),
    ...<2 lines>...
        socket_options=self.socket_options,
    )
  File "C:\Users\–¢–∏–º–∞\PycharmProjects\TelegramBot\venv\Lib\site-packages\urllib3\util\connection.py", line 60, in create_connection
    for res in socket.getaddrinfo(host, port, family, socket.SOCK_STREAM):
               ~~~~~~~~~~~~~~~~~~^^^^^^^^^^^^^^^^^^^^^^^^^^^^^^^^^^^^^^^^
  File "C:\Program Files\Python313\Lib\socket.py", line 975, in getaddrinfo
    for res in _socket.getaddrinfo(host, port, family, type, proto, flags):
               ~~~~~~~~~~~~~~~~~~~^^^^^^^^^^^^^^^^^^^^^^^^^^^^^^^^^^^^^^^^
socket.gaierror: [Errno 11001] getaddrinfo failed

The above exception was the direct cause of the following exception:

Traceback (most recent call last):
  File "C:\Users\–¢–∏–º–∞\PycharmProjects\TelegramBot\venv\Lib\site-packages\urllib3\connectionpool.py", line 787, in urlopen
    response = self._make_request(
        conn,
    ...<10 lines>...
        **response_kw,
    )
  File "C:\Users\–¢–∏–º–∞\PycharmProjects\TelegramBot\venv\Lib\site-packages\urllib3\connectionpool.py", line 488, in _make_request
    raise new_e
  File "C:\Users\–¢–∏–º–∞\PycharmProjects\TelegramBot\venv\Lib\site-packages\urllib3\connectionpool.py", line 464, in _make_request
    self._validate_conn(conn)
    ~~~~~~~~~~~~~~~~~~~^^^^^^
  File "C:\Users\–¢–∏–º–∞\PycharmProjects\TelegramBot\venv\Lib\site-packages\urllib3\connectionpool.py", line 1093, in _validate_conn
    conn.connect()
    ~~~~~~~~~~~~^^
  File "C:\Users\–¢–∏–º–∞\PycharmProjects\TelegramBot\venv\Lib\site-packages\urllib3\connection.py", line 704, in connect
    self.sock = sock = self._new_conn()
                       ~~~~~~~~~~~~~~^^
  File "C:\Users\–¢–∏–º–∞\PycharmProjects\TelegramBot\venv\Lib\site-packages\urllib3\connection.py", line 205, in _new_conn
    raise NameResolutionError(self.host, self, e) from e
urllib3.exceptions.NameResolutionError: <urllib3.connection.HTTPSConnection object at 0x000002C37038FED0>: Failed to resolve 'api.telegram.org' ([Errno 11001] getaddrinfo failed)

The above exception was the direct cause of the following exception:

Traceback (most recent call last):
  File "C:\Users\–¢–∏–º–∞\PycharmProjects\TelegramBot\venv\Lib\site-packages\requests\adapters.py", line 667, in send
    resp = conn.urlopen(
        method=request.method,
    ...<9 lines>...
        chunked=chunked,
    )
  File "C:\Users\–¢–∏–º–∞\PycharmProjects\TelegramBot\venv\Lib\site-packages\urllib3\connectionpool.py", line 841, in urlopen
    retries = retries.increment(
        method, url, error=new_e, _pool=self, _stacktrace=sys.exc_info()[2]
    )
  File "C:\Users\–¢–∏–º–∞\PycharmProjects\TelegramBot\venv\Lib\site-packages\urllib3\util\retry.py", line 519, in increment
    raise MaxRetryError(_pool, url, reason) from reason  # type: ignore[arg-type]
    ^^^^^^^^^^^^^^^^^^^^^^^^^^^^^^^^^^^^^^^^^^^^^^^^^^^
urllib3.exceptions.MaxRetryError: HTTPSConnectionPool(host='api.telegram.org', port=443): Max retries exceeded with url: /bot7221935484:***********************************/getUpdates?offset=901297587&timeout=20 (Caused by NameResolutionError("<urllib3.connection.HTTPSConnection object at 0x000002C37038FED0>: Failed to resolve 'api.telegram.org' ([Errno 11001] getaddrinfo failed)"))

During handling of the above exception, another exception occurred:

Traceback (most recent call last):
  File "C:\Users\–¢–∏–º–∞\PycharmProjects\TelegramBot\venv\Lib\site-packages\telebot\__init__.py", line 1110, in infinity_polling
    self.polling(non_stop=True, timeout=timeout, long_polling_timeout=long_polling_timeout,
    ~~~~~~~~~~~~^^^^^^^^^^^^^^^^^^^^^^^^^^^^^^^^^^^^^^^^^^^^^^^^^^^^^^^^^^^^^^^^^^^^^^^^^^^
                 logger_level=logger_level, allowed_updates=allowed_updates, restart_on_change=False,
                 ^^^^^^^^^^^^^^^^^^^^^^^^^^^^^^^^^^^^^^^^^^^^^^^^^^^^^^^^^^^^^^^^^^^^^^^^^^^^^^^^^^^^
                 *args, **kwargs)
                 ^^^^^^^^^^^^^^^^
  File "C:\Users\–¢–∏–º–∞\PycharmProjects\TelegramBot\venv\Lib\site-packages\telebot\__init__.py", line 1198, in polling
    self.__threaded_polling(non_stop=non_stop, interval=interval, timeout=timeout, long_polling_timeout=long_polling_timeout,
    ~~~~~~~~~~~~~~~~~~~~~~~^^^^^^^^^^^^^^^^^^^^^^^^^^^^^^^^^^^^^^^^^^^^^^^^^^^^^^^^^^^^^^^^^^^^^^^^^^^^^^^^^^^^^^^^^^^^^^^^^^
                            logger_level=logger_level, allowed_updates=allowed_updates)
                            ^^^^^^^^^^^^^^^^^^^^^^^^^^^^^^^^^^^^^^^^^^^^^^^^^^^^^^^^^^^
  File "C:\Users\–¢–∏–º–∞\PycharmProjects\TelegramBot\venv\Lib\site-packages\telebot\__init__.py", line 1273, in __threaded_polling
    raise e
  File "C:\Users\–¢–∏–º–∞\PycharmProjects\TelegramBot\venv\Lib\site-packages\telebot\__init__.py", line 1234, in __threaded_polling
    polling_thread.raise_exceptions()
    ~~~~~~~~~~~~~~~~~~~~~~~~~~~~~~~^^
  File "C:\Users\–¢–∏–º–∞\PycharmProjects\TelegramBot\venv\Lib\site-packages\telebot\util.py", line 111, in raise_exceptions
    raise self.exception_info
  File "C:\Users\–¢–∏–º–∞\PycharmProjects\TelegramBot\venv\Lib\site-packages\telebot\util.py", line 93, in run
    task(*args, **kwargs)
    ~~~~^^^^^^^^^^^^^^^^^
  File "C:\Users\–¢–∏–º–∞\PycharmProjects\TelegramBot\venv\Lib\site-packages\telebot\__init__.py", line 688, in __retrieve_updates
    updates = self.get_updates(offset=(self.last_update_id + 1),
                               allowed_updates=allowed_updates,
                               timeout=timeout, long_polling_timeout=long_polling_timeout)
  File "C:\Users\–¢–∏–º–∞\PycharmProjects\TelegramBot\venv\Lib\site-packages\telebot\__init__.py", line 660, in get_updates
    json_updates = apihelper.get_updates(
        self.token, offset=offset, limit=limit, timeout=timeout, allowed_updates=allowed_updates,
        long_polling_timeout=long_polling_timeout)
  File "C:\Users\–¢–∏–º–∞\PycharmProjects\TelegramBot\venv\Lib\site-packages\telebot\apihelper.py", line 332, in get_updates
    return _make_request(token, method_url, params=payload)
  File "C:\Users\–¢–∏–º–∞\PycharmProjects\TelegramBot\venv\Lib\site-packages\telebot\apihelper.py", line 162, in _make_request
    result = _get_req_session().request(
        method, request_url, params=params, files=files,
        timeout=(connect_timeout, read_timeout), proxies=proxy)
  File "C:\Users\–¢–∏–º–∞\PycharmProjects\TelegramBot\venv\Lib\site-packages\requests\sessions.py", line 589, in request
    resp = self.send(prep, **send_kwargs)
  File "C:\Users\–¢–∏–º–∞\PycharmProjects\TelegramBot\venv\Lib\site-packages\requests\sessions.py", line 703, in send
    r = adapter.send(request, **kwargs)
  File "C:\Users\–¢–∏–º–∞\PycharmProjects\TelegramBot\venv\Lib\site-packages\requests\adapters.py", line 700, in send
    raise ConnectionError(e, request=request)
requests.exceptions.ConnectionError: HTTPSConnectionPool(host='api.telegram.org', port=443): Max retries exceeded with url: /bot7221935484:***********************************/getUpdates?offset=901297587&timeout=20 (Caused by NameResolutionError("<urllib3.connection.HTTPSConnection object at 0x000002C37038FED0>: Failed to resolve 'api.telegram.org' ([Errno 11001] getaddrinfo failed)"))

2025-02-03 15 - TeleBot - ERROR - Infinity polling exception: HTTPSConnectionPool(host='api.telegram.org', port=443): Max retries exceeded with url: /bot7221935484:***********************************/getUpdates?offset=901297587&timeout=20 (Caused by NameResolutionError("<urllib3.connection.HTTPSConnection object at 0x000002C371A00410>: Failed to resolve 'api.telegram.org' ([Errno 11001] getaddrinfo failed)"))
2025-02-03 15 - TeleBot - ERROR - Exception traceback:
Traceback (most recent call last):
  File "C:\Users\–¢–∏–º–∞\PycharmProjects\TelegramBot\venv\Lib\site-packages\urllib3\connection.py", line 198, in _new_conn
    sock = connection.create_connection(
        (self._dns_host, self.port),
    ...<2 lines>...
        socket_options=self.socket_options,
    )
  File "C:\Users\–¢–∏–º–∞\PycharmProjects\TelegramBot\venv\Lib\site-packages\urllib3\util\connection.py", line 60, in create_connection
    for res in socket.getaddrinfo(host, port, family, socket.SOCK_STREAM):
               ~~~~~~~~~~~~~~~~~~^^^^^^^^^^^^^^^^^^^^^^^^^^^^^^^^^^^^^^^^
  File "C:\Program Files\Python313\Lib\socket.py", line 975, in getaddrinfo
    for res in _socket.getaddrinfo(host, port, family, type, proto, flags):
               ~~~~~~~~~~~~~~~~~~~^^^^^^^^^^^^^^^^^^^^^^^^^^^^^^^^^^^^^^^^
socket.gaierror: [Errno 11001] getaddrinfo failed

The above exception was the direct cause of the following exception:

Traceback (most recent call last):
  File "C:\Users\–¢–∏–º–∞\PycharmProjects\TelegramBot\venv\Lib\site-packages\urllib3\connectionpool.py", line 787, in urlopen
    response = self._make_request(
        conn,
    ...<10 lines>...
        **response_kw,
    )
  File "C:\Users\–¢–∏–º–∞\PycharmProjects\TelegramBot\venv\Lib\site-packages\urllib3\connectionpool.py", line 488, in _make_request
    raise new_e
  File "C:\Users\–¢–∏–º–∞\PycharmProjects\TelegramBot\venv\Lib\site-packages\urllib3\connectionpool.py", line 464, in _make_request
    self._validate_conn(conn)
    ~~~~~~~~~~~~~~~~~~~^^^^^^
  File "C:\Users\–¢–∏–º–∞\PycharmProjects\TelegramBot\venv\Lib\site-packages\urllib3\connectionpool.py", line 1093, in _validate_conn
    conn.connect()
    ~~~~~~~~~~~~^^
  File "C:\Users\–¢–∏–º–∞\PycharmProjects\TelegramBot\venv\Lib\site-packages\urllib3\connection.py", line 704, in connect
    self.sock = sock = self._new_conn()
                       ~~~~~~~~~~~~~~^^
  File "C:\Users\–¢–∏–º–∞\PycharmProjects\TelegramBot\venv\Lib\site-packages\urllib3\connection.py", line 205, in _new_conn
    raise NameResolutionError(self.host, self, e) from e
urllib3.exceptions.NameResolutionError: <urllib3.connection.HTTPSConnection object at 0x000002C371A00410>: Failed to resolve 'api.telegram.org' ([Errno 11001] getaddrinfo failed)

The above exception was the direct cause of the following exception:

Traceback (most recent call last):
  File "C:\Users\–¢–∏–º–∞\PycharmProjects\TelegramBot\venv\Lib\site-packages\requests\adapters.py", line 667, in send
    resp = conn.urlopen(
        method=request.method,
    ...<9 lines>...
        chunked=chunked,
    )
  File "C:\Users\–¢–∏–º–∞\PycharmProjects\TelegramBot\venv\Lib\site-packages\urllib3\connectionpool.py", line 841, in urlopen
    retries = retries.increment(
        method, url, error=new_e, _pool=self, _stacktrace=sys.exc_info()[2]
    )
  File "C:\Users\–¢–∏–º–∞\PycharmProjects\TelegramBot\venv\Lib\site-packages\urllib3\util\retry.py", line 519, in increment
    raise MaxRetryError(_pool, url, reason) from reason  # type: ignore[arg-type]
    ^^^^^^^^^^^^^^^^^^^^^^^^^^^^^^^^^^^^^^^^^^^^^^^^^^^
urllib3.exceptions.MaxRetryError: HTTPSConnectionPool(host='api.telegram.org', port=443): Max retries exceeded with url: /bot7221935484:***********************************/getUpdates?offset=901297587&timeout=20 (Caused by NameResolutionError("<urllib3.connection.HTTPSConnection object at 0x000002C371A00410>: Failed to resolve 'api.telegram.org' ([Errno 11001] getaddrinfo failed)"))

During handling of the above exception, another exception occurred:

Traceback (most recent call last):
  File "C:\Users\–¢–∏–º–∞\PycharmProjects\TelegramBot\venv\Lib\site-packages\telebot\__init__.py", line 1110, in infinity_polling
    self.polling(non_stop=True, timeout=timeout, long_polling_timeout=long_polling_timeout,
    ~~~~~~~~~~~~^^^^^^^^^^^^^^^^^^^^^^^^^^^^^^^^^^^^^^^^^^^^^^^^^^^^^^^^^^^^^^^^^^^^^^^^^^^
                 logger_level=logger_level, allowed_updates=allowed_updates, restart_on_change=False,
                 ^^^^^^^^^^^^^^^^^^^^^^^^^^^^^^^^^^^^^^^^^^^^^^^^^^^^^^^^^^^^^^^^^^^^^^^^^^^^^^^^^^^^
                 *args, **kwargs)
                 ^^^^^^^^^^^^^^^^
  File "C:\Users\–¢–∏–º–∞\PycharmProjects\TelegramBot\venv\Lib\site-packages\telebot\__init__.py", line 1198, in polling
    self.__threaded_polling(non_stop=non_stop, interval=interval, timeout=timeout, long_polling_timeout=long_polling_timeout,
    ~~~~~~~~~~~~~~~~~~~~~~~^^^^^^^^^^^^^^^^^^^^^^^^^^^^^^^^^^^^^^^^^^^^^^^^^^^^^^^^^^^^^^^^^^^^^^^^^^^^^^^^^^^^^^^^^^^^^^^^^^
                            logger_level=logger_level, allowed_updates=allowed_updates)
                            ^^^^^^^^^^^^^^^^^^^^^^^^^^^^^^^^^^^^^^^^^^^^^^^^^^^^^^^^^^^
  File "C:\Users\–¢–∏–º–∞\PycharmProjects\TelegramBot\venv\Lib\site-packages\telebot\__init__.py", line 1273, in __threaded_polling
    raise e
  File "C:\Users\–¢–∏–º–∞\PycharmProjects\TelegramBot\venv\Lib\site-packages\telebot\__init__.py", line 1234, in __threaded_polling
    polling_thread.raise_exceptions()
    ~~~~~~~~~~~~~~~~~~~~~~~~~~~~~~~^^
  File "C:\Users\–¢–∏–º–∞\PycharmProjects\TelegramBot\venv\Lib\site-packages\telebot\util.py", line 111, in raise_exceptions
    raise self.exception_info
  File "C:\Users\–¢–∏–º–∞\PycharmProjects\TelegramBot\venv\Lib\site-packages\telebot\util.py", line 93, in run
    task(*args, **kwargs)
    ~~~~^^^^^^^^^^^^^^^^^
  File "C:\Users\–¢–∏–º–∞\PycharmProjects\TelegramBot\venv\Lib\site-packages\telebot\__init__.py", line 688, in __retrieve_updates
    updates = self.get_updates(offset=(self.last_update_id + 1),
                               allowed_updates=allowed_updates,
                               timeout=timeout, long_polling_timeout=long_polling_timeout)
  File "C:\Users\–¢–∏–º–∞\PycharmProjects\TelegramBot\venv\Lib\site-packages\telebot\__init__.py", line 660, in get_updates
    json_updates = apihelper.get_updates(
        self.token, offset=offset, limit=limit, timeout=timeout, allowed_updates=allowed_updates,
        long_polling_timeout=long_polling_timeout)
  File "C:\Users\–¢–∏–º–∞\PycharmProjects\TelegramBot\venv\Lib\site-packages\telebot\apihelper.py", line 332, in get_updates
    return _make_request(token, method_url, params=payload)
  File "C:\Users\–¢–∏–º–∞\PycharmProjects\TelegramBot\venv\Lib\site-packages\telebot\apihelper.py", line 162, in _make_request
    result = _get_req_session().request(
        method, request_url, params=params, files=files,
        timeout=(connect_timeout, read_timeout), proxies=proxy)
  File "C:\Users\–¢–∏–º–∞\PycharmProjects\TelegramBot\venv\Lib\site-packages\requests\sessions.py", line 589, in request
    resp = self.send(prep, **send_kwargs)
  File "C:\Users\–¢–∏–º–∞\PycharmProjects\TelegramBot\venv\Lib\site-packages\requests\sessions.py", line 703, in send
    r = adapter.send(request, **kwargs)
  File "C:\Users\–¢–∏–º–∞\PycharmProjects\TelegramBot\venv\Lib\site-packages\requests\adapters.py", line 700, in send
    raise ConnectionError(e, request=request)
requests.exceptions.ConnectionError: HTTPSConnectionPool(host='api.telegram.org', port=443): Max retries exceeded with url: /bot7221935484:***********************************/getUpdates?offset=901297587&timeout=20 (Caused by NameResolutionError("<urllib3.connection.HTTPSConnection object at 0x000002C371A00410>: Failed to resolve 'api.telegram.org' ([Errno 11001] getaddrinfo failed)"))

2025-02-03 15 - TeleBot - ERROR - Infinity polling exception: HTTPSConnectionPool(host='api.telegram.org', port=443): Max retries exceeded with url: /bot7221935484:***********************************/getUpdates?offset=901297587&timeout=20 (Caused by NameResolutionError("<urllib3.connection.HTTPSConnection object at 0x000002C371A00910>: Failed to resolve 'api.telegram.org' ([Errno 11001] getaddrinfo failed)"))
2025-02-03 15 - TeleBot - ERROR - Exception traceback:
Traceback (most recent call last):
  File "C:\Users\–¢–∏–º–∞\PycharmProjects\TelegramBot\venv\Lib\site-packages\urllib3\connection.py", line 198, in _new_conn
    sock = connection.create_connection(
        (self._dns_host, self.port),
    ...<2 lines>...
        socket_options=self.socket_options,
    )
  File "C:\Users\–¢–∏–º–∞\PycharmProjects\TelegramBot\venv\Lib\site-packages\urllib3\util\connection.py", line 60, in create_connection
    for res in socket.getaddrinfo(host, port, family, socket.SOCK_STREAM):
               ~~~~~~~~~~~~~~~~~~^^^^^^^^^^^^^^^^^^^^^^^^^^^^^^^^^^^^^^^^
  File "C:\Program Files\Python313\Lib\socket.py", line 975, in getaddrinfo
    for res in _socket.getaddrinfo(host, port, family, type, proto, flags):
               ~~~~~~~~~~~~~~~~~~~^^^^^^^^^^^^^^^^^^^^^^^^^^^^^^^^^^^^^^^^
socket.gaierror: [Errno 11001] getaddrinfo failed

The above exception was the direct cause of the following exception:

Traceback (most recent call last):
  File "C:\Users\–¢–∏–º–∞\PycharmProjects\TelegramBot\venv\Lib\site-packages\urllib3\connectionpool.py", line 787, in urlopen
    response = self._make_request(
        conn,
    ...<10 lines>...
        **response_kw,
    )
  File "C:\Users\–¢–∏–º–∞\PycharmProjects\TelegramBot\venv\Lib\site-packages\urllib3\connectionpool.py", line 488, in _make_request
    raise new_e
  File "C:\Users\–¢–∏–º–∞\PycharmProjects\TelegramBot\venv\Lib\site-packages\urllib3\connectionpool.py", line 464, in _make_request
    self._validate_conn(conn)
    ~~~~~~~~~~~~~~~~~~~^^^^^^
  File "C:\Users\–¢–∏–º–∞\PycharmProjects\TelegramBot\venv\Lib\site-packages\urllib3\connectionpool.py", line 1093, in _validate_conn
    conn.connect()
    ~~~~~~~~~~~~^^
  File "C:\Users\–¢–∏–º–∞\PycharmProjects\TelegramBot\venv\Lib\site-packages\urllib3\connection.py", line 704, in connect
    self.sock = sock = self._new_conn()
                       ~~~~~~~~~~~~~~^^
  File "C:\Users\–¢–∏–º–∞\PycharmProjects\TelegramBot\venv\Lib\site-packages\urllib3\connection.py", line 205, in _new_conn
    raise NameResolutionError(self.host, self, e) from e
urllib3.exceptions.NameResolutionError: <urllib3.connection.HTTPSConnection object at 0x000002C371A00910>: Failed to resolve 'api.telegram.org' ([Errno 11001] getaddrinfo failed)

The above exception was the direct cause of the following exception:

Traceback (most recent call last):
  File "C:\Users\–¢–∏–º–∞\PycharmProjects\TelegramBot\venv\Lib\site-packages\requests\adapters.py", line 667, in send
    resp = conn.urlopen(
        method=request.method,
    ...<9 lines>...
        chunked=chunked,
    )
  File "C:\Users\–¢–∏–º–∞\PycharmProjects\TelegramBot\venv\Lib\site-packages\urllib3\connectionpool.py", line 841, in urlopen
    retries = retries.increment(
        method, url, error=new_e, _pool=self, _stacktrace=sys.exc_info()[2]
    )
  File "C:\Users\–¢–∏–º–∞\PycharmProjects\TelegramBot\venv\Lib\site-packages\urllib3\util\retry.py", line 519, in increment
    raise MaxRetryError(_pool, url, reason) from reason  # type: ignore[arg-type]
    ^^^^^^^^^^^^^^^^^^^^^^^^^^^^^^^^^^^^^^^^^^^^^^^^^^^
urllib3.exceptions.MaxRetryError: HTTPSConnectionPool(host='api.telegram.org', port=443): Max retries exceeded with url: /bot7221935484:***********************************/getUpdates?offset=901297587&timeout=20 (Caused by NameResolutionError("<urllib3.connection.HTTPSConnection object at 0x000002C371A00910>: Failed to resolve 'api.telegram.org' ([Errno 11001] getaddrinfo failed)"))

During handling of the above exception, another exception occurred:

Traceback (most recent call last):
  File "C:\Users\–¢–∏–º–∞\PycharmProjects\TelegramBot\venv\Lib\site-packages\telebot\__init__.py", line 1110, in infinity_polling
    self.polling(non_stop=True, timeout=timeout, long_polling_timeout=long_polling_timeout,
    ~~~~~~~~~~~~^^^^^^^^^^^^^^^^^^^^^^^^^^^^^^^^^^^^^^^^^^^^^^^^^^^^^^^^^^^^^^^^^^^^^^^^^^^
                 logger_level=logger_level, allowed_updates=allowed_updates, restart_on_change=False,
                 ^^^^^^^^^^^^^^^^^^^^^^^^^^^^^^^^^^^^^^^^^^^^^^^^^^^^^^^^^^^^^^^^^^^^^^^^^^^^^^^^^^^^
                 *args, **kwargs)
                 ^^^^^^^^^^^^^^^^
  File "C:\Users\–¢–∏–º–∞\PycharmProjects\TelegramBot\venv\Lib\site-packages\telebot\__init__.py", line 1198, in polling
    self.__threaded_polling(non_stop=non_stop, interval=interval, timeout=timeout, long_polling_timeout=long_polling_timeout,
    ~~~~~~~~~~~~~~~~~~~~~~~^^^^^^^^^^^^^^^^^^^^^^^^^^^^^^^^^^^^^^^^^^^^^^^^^^^^^^^^^^^^^^^^^^^^^^^^^^^^^^^^^^^^^^^^^^^^^^^^^^
                            logger_level=logger_level, allowed_updates=allowed_updates)
                            ^^^^^^^^^^^^^^^^^^^^^^^^^^^^^^^^^^^^^^^^^^^^^^^^^^^^^^^^^^^
  File "C:\Users\–¢–∏–º–∞\PycharmProjects\TelegramBot\venv\Lib\site-packages\telebot\__init__.py", line 1273, in __threaded_polling
    raise e
  File "C:\Users\–¢–∏–º–∞\PycharmProjects\TelegramBot\venv\Lib\site-packages\telebot\__init__.py", line 1234, in __threaded_polling
    polling_thread.raise_exceptions()
    ~~~~~~~~~~~~~~~~~~~~~~~~~~~~~~~^^
  File "C:\Users\–¢–∏–º–∞\PycharmProjects\TelegramBot\venv\Lib\site-packages\telebot\util.py", line 111, in raise_exceptions
    raise self.exception_info
  File "C:\Users\–¢–∏–º–∞\PycharmProjects\TelegramBot\venv\Lib\site-packages\telebot\util.py", line 93, in run
    task(*args, **kwargs)
    ~~~~^^^^^^^^^^^^^^^^^
  File "C:\Users\–¢–∏–º–∞\PycharmProjects\TelegramBot\venv\Lib\site-packages\telebot\__init__.py", line 688, in __retrieve_updates
    updates = self.get_updates(offset=(self.last_update_id + 1),
                               allowed_updates=allowed_updates,
                               timeout=timeout, long_polling_timeout=long_polling_timeout)
  File "C:\Users\–¢–∏–º–∞\PycharmProjects\TelegramBot\venv\Lib\site-packages\telebot\__init__.py", line 660, in get_updates
    json_updates = apihelper.get_updates(
        self.token, offset=offset, limit=limit, timeout=timeout, allowed_updates=allowed_updates,
        long_polling_timeout=long_polling_timeout)
  File "C:\Users\–¢–∏–º–∞\PycharmProjects\TelegramBot\venv\Lib\site-packages\telebot\apihelper.py", line 332, in get_updates
    return _make_request(token, method_url, params=payload)
  File "C:\Users\–¢–∏–º–∞\PycharmProjects\TelegramBot\venv\Lib\site-packages\telebot\apihelper.py", line 162, in _make_request
    result = _get_req_session().request(
        method, request_url, params=params, files=files,
        timeout=(connect_timeout, read_timeout), proxies=proxy)
  File "C:\Users\–¢–∏–º–∞\PycharmProjects\TelegramBot\venv\Lib\site-packages\requests\sessions.py", line 589, in request
    resp = self.send(prep, **send_kwargs)
  File "C:\Users\–¢–∏–º–∞\PycharmProjects\TelegramBot\venv\Lib\site-packages\requests\sessions.py", line 703, in send
    r = adapter.send(request, **kwargs)
  File "C:\Users\–¢–∏–º–∞\PycharmProjects\TelegramBot\venv\Lib\site-packages\requests\adapters.py", line 700, in send
    raise ConnectionError(e, request=request)
requests.exceptions.ConnectionError: HTTPSConnectionPool(host='api.telegram.org', port=443): Max retries exceeded with url: /bot7221935484:***********************************/getUpdates?offset=901297587&timeout=20 (Caused by NameResolutionError("<urllib3.connection.HTTPSConnection object at 0x000002C371A00910>: Failed to resolve 'api.telegram.org' ([Errno 11001] getaddrinfo failed)"))

2025-02-03 15 - root - INFO - DATABASE: 5948417394 –ø–æ—Ç—Ä–∞—Ç–∏–ª 10000 —Ç–æ–∫–µ–Ω–æ–≤
2025-02-03 15 - TeleBot - ERROR - Infinity polling: polling exited
2025-02-03 15 - TeleBot - ERROR - Break infinity polling
2025-02-03 15 - root - INFO - DATABASE: 5948417394 –ø–æ—Ç—Ä–∞—Ç–∏–ª 10000 —Ç–æ–∫–µ–Ω–æ–≤
2025-02-03 16 - root - INFO - DATABASE: 5948417394 –ø–æ—Ç—Ä–∞—Ç–∏–ª 10000 —Ç–æ–∫–µ–Ω–æ–≤
2025-02-03 16 - root - INFO - DATABASE: 5948417394 –ø–æ—Ç—Ä–∞—Ç–∏–ª 10000 —Ç–æ–∫–µ–Ω–æ–≤
2025-02-03 16 - root - INFO - DATABASE: 5948417394 –ø–æ—Ç—Ä–∞—Ç–∏–ª 10000 —Ç–æ–∫–µ–Ω–æ–≤
2025-02-03 16 - root - INFO - DATABASE: 5948417394 –ø–æ—Ç—Ä–∞—Ç–∏–ª 10000 —Ç–æ–∫–µ–Ω–æ–≤
2025-02-03 16 - TeleBot - ERROR - Infinity polling: polling exited
2025-02-03 16 - TeleBot - ERROR - Break infinity polling
2025-02-03 16 - TeleBot - ERROR - Infinity polling exception: '/start'
2025-02-03 16 - TeleBot - ERROR - Exception traceback:
Traceback (most recent call last):
  File "C:\Users\–¢–∏–º–∞\PycharmProjects\TelegramBot\venv\Lib\site-packages\telebot\__init__.py", line 1110, in infinity_polling
    self.polling(non_stop=True, timeout=timeout, long_polling_timeout=long_polling_timeout,
    ~~~~~~~~~~~~^^^^^^^^^^^^^^^^^^^^^^^^^^^^^^^^^^^^^^^^^^^^^^^^^^^^^^^^^^^^^^^^^^^^^^^^^^^
                 logger_level=logger_level, allowed_updates=allowed_updates, restart_on_change=False,
                 ^^^^^^^^^^^^^^^^^^^^^^^^^^^^^^^^^^^^^^^^^^^^^^^^^^^^^^^^^^^^^^^^^^^^^^^^^^^^^^^^^^^^
                 *args, **kwargs)
                 ^^^^^^^^^^^^^^^^
  File "C:\Users\–¢–∏–º–∞\PycharmProjects\TelegramBot\venv\Lib\site-packages\telebot\__init__.py", line 1198, in polling
    self.__threaded_polling(non_stop=non_stop, interval=interval, timeout=timeout, long_polling_timeout=long_polling_timeout,
    ~~~~~~~~~~~~~~~~~~~~~~~^^^^^^^^^^^^^^^^^^^^^^^^^^^^^^^^^^^^^^^^^^^^^^^^^^^^^^^^^^^^^^^^^^^^^^^^^^^^^^^^^^^^^^^^^^^^^^^^^^
                            logger_level=logger_level, allowed_updates=allowed_updates)
                            ^^^^^^^^^^^^^^^^^^^^^^^^^^^^^^^^^^^^^^^^^^^^^^^^^^^^^^^^^^^
  File "C:\Users\–¢–∏–º–∞\PycharmProjects\TelegramBot\venv\Lib\site-packages\telebot\__init__.py", line 1273, in __threaded_polling
    raise e
  File "C:\Users\–¢–∏–º–∞\PycharmProjects\TelegramBot\venv\Lib\site-packages\telebot\__init__.py", line 1235, in __threaded_polling
    self.worker_pool.raise_exceptions()
    ~~~~~~~~~~~~~~~~~~~~~~~~~~~~~~~~~^^
  File "C:\Users\–¢–∏–º–∞\PycharmProjects\TelegramBot\venv\Lib\site-packages\telebot\util.py", line 150, in raise_exceptions
    raise self.exception_info
  File "C:\Users\–¢–∏–º–∞\PycharmProjects\TelegramBot\venv\Lib\site-packages\telebot\util.py", line 93, in run
    task(*args, **kwargs)
    ~~~~^^^^^^^^^^^^^^^^^
  File "C:\Users\–¢–∏–º–∞\PycharmProjects\TelegramBot\main.py", line 104, in change_settings_handler_2
    if TRANSLATE[msg.text] in settings[str(user_id)].keys():
       ~~~~~~~~~^^^^^^^^^^
KeyError: '/start'

2025-02-03 16 - TeleBot - ERROR - Infinity polling: polling exited
2025-02-03 16 - TeleBot - ERROR - Break infinity polling
2025-02-03 16 - TeleBot - ERROR - Infinity polling exception: 'system_prompt'
2025-02-03 16 - TeleBot - ERROR - Exception traceback:
Traceback (most recent call last):
  File "C:\Users\–¢–∏–º–∞\PycharmProjects\TelegramBot\venv\Lib\site-packages\telebot\__init__.py", line 1110, in infinity_polling
    self.polling(non_stop=True, timeout=timeout, long_polling_timeout=long_polling_timeout,
    ~~~~~~~~~~~~^^^^^^^^^^^^^^^^^^^^^^^^^^^^^^^^^^^^^^^^^^^^^^^^^^^^^^^^^^^^^^^^^^^^^^^^^^^
                 logger_level=logger_level, allowed_updates=allowed_updates, restart_on_change=False,
                 ^^^^^^^^^^^^^^^^^^^^^^^^^^^^^^^^^^^^^^^^^^^^^^^^^^^^^^^^^^^^^^^^^^^^^^^^^^^^^^^^^^^^
                 *args, **kwargs)
                 ^^^^^^^^^^^^^^^^
  File "C:\Users\–¢–∏–º–∞\PycharmProjects\TelegramBot\venv\Lib\site-packages\telebot\__init__.py", line 1198, in polling
    self.__threaded_polling(non_stop=non_stop, interval=interval, timeout=timeout, long_polling_timeout=long_polling_timeout,
    ~~~~~~~~~~~~~~~~~~~~~~~^^^^^^^^^^^^^^^^^^^^^^^^^^^^^^^^^^^^^^^^^^^^^^^^^^^^^^^^^^^^^^^^^^^^^^^^^^^^^^^^^^^^^^^^^^^^^^^^^^
                            logger_level=logger_level, allowed_updates=allowed_updates)
                            ^^^^^^^^^^^^^^^^^^^^^^^^^^^^^^^^^^^^^^^^^^^^^^^^^^^^^^^^^^^
  File "C:\Users\–¢–∏–º–∞\PycharmProjects\TelegramBot\venv\Lib\site-packages\telebot\__init__.py", line 1273, in __threaded_polling
    raise e
  File "C:\Users\–¢–∏–º–∞\PycharmProjects\TelegramBot\venv\Lib\site-packages\telebot\__init__.py", line 1235, in __threaded_polling
    self.worker_pool.raise_exceptions()
    ~~~~~~~~~~~~~~~~~~~~~~~~~~~~~~~~~^^
  File "C:\Users\–¢–∏–º–∞\PycharmProjects\TelegramBot\venv\Lib\site-packages\telebot\util.py", line 150, in raise_exceptions
    raise self.exception_info
  File "C:\Users\–¢–∏–º–∞\PycharmProjects\TelegramBot\venv\Lib\site-packages\telebot\util.py", line 93, in run
    task(*args, **kwargs)
    ~~~~^^^^^^^^^^^^^^^^^
  File "C:\Users\–¢–∏–º–∞\PycharmProjects\TelegramBot\venv\Lib\site-packages\telebot\__init__.py", line 9233, in _run_middlewares_and_handler
    result = handler['function'](message)
  File "C:\Users\–¢–∏–º–∞\PycharmProjects\TelegramBot\main.py", line 84, in show_settings
    k = TRANSLATE[k]
        ~~~~~~~~~^^^
KeyError: 'system_prompt'

2025-02-03 16 - TeleBot - ERROR - Infinity polling: polling exited
2025-02-03 16 - TeleBot - ERROR - Break infinity polling
2025-02-03 16 - TeleBot - ERROR - Infinity polling: polling exited
2025-02-03 16 - TeleBot - ERROR - Break infinity polling
2025-02-03 16 - TeleBot - ERROR - Infinity polling: polling exited
2025-02-03 16 - TeleBot - ERROR - Break infinity polling
2025-02-03 16 - TeleBot - ERROR - Infinity polling: polling exited
2025-02-03 16 - TeleBot - ERROR - Break infinity polling
2025-02-03 16 - TeleBot - ERROR - Infinity polling exception: 'dict' object is not callable
2025-02-03 16 - TeleBot - ERROR - Exception traceback:
Traceback (most recent call last):
  File "C:\Users\–¢–∏–º–∞\PycharmProjects\TelegramBot\venv\Lib\site-packages\telebot\__init__.py", line 1110, in infinity_polling
    self.polling(non_stop=True, timeout=timeout, long_polling_timeout=long_polling_timeout,
    ~~~~~~~~~~~~^^^^^^^^^^^^^^^^^^^^^^^^^^^^^^^^^^^^^^^^^^^^^^^^^^^^^^^^^^^^^^^^^^^^^^^^^^^
                 logger_level=logger_level, allowed_updates=allowed_updates, restart_on_change=False,
                 ^^^^^^^^^^^^^^^^^^^^^^^^^^^^^^^^^^^^^^^^^^^^^^^^^^^^^^^^^^^^^^^^^^^^^^^^^^^^^^^^^^^^
                 *args, **kwargs)
                 ^^^^^^^^^^^^^^^^
  File "C:\Users\–¢–∏–º–∞\PycharmProjects\TelegramBot\venv\Lib\site-packages\telebot\__init__.py", line 1198, in polling
    self.__threaded_polling(non_stop=non_stop, interval=interval, timeout=timeout, long_polling_timeout=long_polling_timeout,
    ~~~~~~~~~~~~~~~~~~~~~~~^^^^^^^^^^^^^^^^^^^^^^^^^^^^^^^^^^^^^^^^^^^^^^^^^^^^^^^^^^^^^^^^^^^^^^^^^^^^^^^^^^^^^^^^^^^^^^^^^^
                            logger_level=logger_level, allowed_updates=allowed_updates)
                            ^^^^^^^^^^^^^^^^^^^^^^^^^^^^^^^^^^^^^^^^^^^^^^^^^^^^^^^^^^^
  File "C:\Users\–¢–∏–º–∞\PycharmProjects\TelegramBot\venv\Lib\site-packages\telebot\__init__.py", line 1273, in __threaded_polling
    raise e
  File "C:\Users\–¢–∏–º–∞\PycharmProjects\TelegramBot\venv\Lib\site-packages\telebot\__init__.py", line 1235, in __threaded_polling
    self.worker_pool.raise_exceptions()
    ~~~~~~~~~~~~~~~~~~~~~~~~~~~~~~~~~^^
  File "C:\Users\–¢–∏–º–∞\PycharmProjects\TelegramBot\venv\Lib\site-packages\telebot\util.py", line 150, in raise_exceptions
    raise self.exception_info
  File "C:\Users\–¢–∏–º–∞\PycharmProjects\TelegramBot\venv\Lib\site-packages\telebot\util.py", line 93, in run
    task(*args, **kwargs)
    ~~~~^^^^^^^^^^^^^^^^^
  File "C:\Users\–¢–∏–º–∞\PycharmProjects\TelegramBot\main.py", line 107, in change_settings_handler_2
    reply_markup=create_keyboard(TRANSLATE(VALUES[msg.text][i]) for i in VALUES[msg.text]))
                 ~~~~~~~~~~~~~~~^^^^^^^^^^^^^^^^^^^^^^^^^^^^^^^^^^^^^^^^^^^^^^^^^^^^^^^^^^
  File "C:\Users\–¢–∏–º–∞\PycharmProjects\TelegramBot\keyboard.py", line 6, in create_keyboard
    for text in texts:
                ^^^^^
  File "C:\Users\–¢–∏–º–∞\PycharmProjects\TelegramBot\main.py", line 107, in <genexpr>
    reply_markup=create_keyboard(TRANSLATE(VALUES[msg.text][i]) for i in VALUES[msg.text]))
                                 ~~~~~~~~~^^^^^^^^^^^^^^^^^^^^^
TypeError: 'dict' object is not callable

2025-02-03 16 - TeleBot - ERROR - Infinity polling: polling exited
2025-02-03 16 - TeleBot - ERROR - Break infinity polling
2025-02-03 16 - TeleBot - ERROR - Infinity polling: polling exited
2025-02-03 16 - TeleBot - ERROR - Break infinity polling
2025-02-03 17 - TeleBot - ERROR - Infinity polling: polling exited
2025-02-03 17 - TeleBot - ERROR - Break infinity polling
2025-02-03 17 - root - INFO - DATABASE: 5948417394 –ø–æ—Ç—Ä–∞—Ç–∏–ª 10000 —Ç–æ–∫–µ–Ω–æ–≤
2025-02-03 17 - TeleBot - ERROR - Infinity polling exception: '–í–∞–ª–µ—Ä–∞'
2025-02-03 17 - TeleBot - ERROR - Exception traceback:
Traceback (most recent call last):
  File "C:\Users\–¢–∏–º–∞\PycharmProjects\TelegramBot\venv\Lib\site-packages\telebot\__init__.py", line 1110, in infinity_polling
    self.polling(non_stop=True, timeout=timeout, long_polling_timeout=long_polling_timeout,
    ~~~~~~~~~~~~^^^^^^^^^^^^^^^^^^^^^^^^^^^^^^^^^^^^^^^^^^^^^^^^^^^^^^^^^^^^^^^^^^^^^^^^^^^
                 logger_level=logger_level, allowed_updates=allowed_updates, restart_on_change=False,
                 ^^^^^^^^^^^^^^^^^^^^^^^^^^^^^^^^^^^^^^^^^^^^^^^^^^^^^^^^^^^^^^^^^^^^^^^^^^^^^^^^^^^^
                 *args, **kwargs)
                 ^^^^^^^^^^^^^^^^
  File "C:\Users\–¢–∏–º–∞\PycharmProjects\TelegramBot\venv\Lib\site-packages\telebot\__init__.py", line 1198, in polling
    self.__threaded_polling(non_stop=non_stop, interval=interval, timeout=timeout, long_polling_timeout=long_polling_timeout,
    ~~~~~~~~~~~~~~~~~~~~~~~^^^^^^^^^^^^^^^^^^^^^^^^^^^^^^^^^^^^^^^^^^^^^^^^^^^^^^^^^^^^^^^^^^^^^^^^^^^^^^^^^^^^^^^^^^^^^^^^^^
                            logger_level=logger_level, allowed_updates=allowed_updates)
                            ^^^^^^^^^^^^^^^^^^^^^^^^^^^^^^^^^^^^^^^^^^^^^^^^^^^^^^^^^^^
  File "C:\Users\–¢–∏–º–∞\PycharmProjects\TelegramBot\venv\Lib\site-packages\telebot\__init__.py", line 1273, in __threaded_polling
    raise e
  File "C:\Users\–¢–∏–º–∞\PycharmProjects\TelegramBot\venv\Lib\site-packages\telebot\__init__.py", line 1235, in __threaded_polling
    self.worker_pool.raise_exceptions()
    ~~~~~~~~~~~~~~~~~~~~~~~~~~~~~~~~~^^
  File "C:\Users\–¢–∏–º–∞\PycharmProjects\TelegramBot\venv\Lib\site-packages\telebot\util.py", line 150, in raise_exceptions
    raise self.exception_info
  File "C:\Users\–¢–∏–º–∞\PycharmProjects\TelegramBot\venv\Lib\site-packages\telebot\util.py", line 93, in run
    task(*args, **kwargs)
    ~~~~^^^^^^^^^^^^^^^^^
  File "C:\Users\–¢–∏–º–∞\PycharmProjects\TelegramBot\main.py", line 105, in change_settings_handler_2
    if TRANSLATE[msg.text] in settings[str(user_id)].keys():
       ~~~~~~~~~^^^^^^^^^^
KeyError: '–í–∞–ª–µ—Ä–∞'

2025-02-03 17 - TeleBot - ERROR - Infinity polling: polling exited
2025-02-03 17 - TeleBot - ERROR - Break infinity polling
2025-02-03 17 - root - INFO - '–í–∞—Å—è'
2025-02-03 17 - TeleBot - ERROR - Infinity polling exception: '–í–∞—Å—è'
2025-02-03 17 - TeleBot - ERROR - Exception traceback:
Traceback (most recent call last):
  File "C:\Users\–¢–∏–º–∞\PycharmProjects\TelegramBot\venv\Lib\site-packages\telebot\__init__.py", line 1110, in infinity_polling
    self.polling(non_stop=True, timeout=timeout, long_polling_timeout=long_polling_timeout,
    ~~~~~~~~~~~~^^^^^^^^^^^^^^^^^^^^^^^^^^^^^^^^^^^^^^^^^^^^^^^^^^^^^^^^^^^^^^^^^^^^^^^^^^^
                 logger_level=logger_level, allowed_updates=allowed_updates, restart_on_change=False,
                 ^^^^^^^^^^^^^^^^^^^^^^^^^^^^^^^^^^^^^^^^^^^^^^^^^^^^^^^^^^^^^^^^^^^^^^^^^^^^^^^^^^^^
                 *args, **kwargs)
                 ^^^^^^^^^^^^^^^^
  File "C:\Users\–¢–∏–º–∞\PycharmProjects\TelegramBot\venv\Lib\site-packages\telebot\__init__.py", line 1198, in polling
    self.__threaded_polling(non_stop=non_stop, interval=interval, timeout=timeout, long_polling_timeout=long_polling_timeout,
    ~~~~~~~~~~~~~~~~~~~~~~~^^^^^^^^^^^^^^^^^^^^^^^^^^^^^^^^^^^^^^^^^^^^^^^^^^^^^^^^^^^^^^^^^^^^^^^^^^^^^^^^^^^^^^^^^^^^^^^^^^
                            logger_level=logger_level, allowed_updates=allowed_updates)
                            ^^^^^^^^^^^^^^^^^^^^^^^^^^^^^^^^^^^^^^^^^^^^^^^^^^^^^^^^^^^
  File "C:\Users\–¢–∏–º–∞\PycharmProjects\TelegramBot\venv\Lib\site-packages\telebot\__init__.py", line 1273, in __threaded_polling
    raise e
  File "C:\Users\–¢–∏–º–∞\PycharmProjects\TelegramBot\venv\Lib\site-packages\telebot\__init__.py", line 1235, in __threaded_polling
    self.worker_pool.raise_exceptions()
    ~~~~~~~~~~~~~~~~~~~~~~~~~~~~~~~~~^^
  File "C:\Users\–¢–∏–º–∞\PycharmProjects\TelegramBot\venv\Lib\site-packages\telebot\util.py", line 150, in raise_exceptions
    raise self.exception_info
  File "C:\Users\–¢–∏–º–∞\PycharmProjects\TelegramBot\venv\Lib\site-packages\telebot\util.py", line 93, in run
    task(*args, **kwargs)
    ~~~~^^^^^^^^^^^^^^^^^
  File "C:\Users\–¢–∏–º–∞\PycharmProjects\TelegramBot\main.py", line 114, in change_settings_handler_2
    if TRANSLATE[msg.text] in settings[str(user_id)].keys():
       ~~~~~~~~~^^^^^^^^^^
KeyError: '–í–∞—Å—è'

2025-02-03 17 - TeleBot - ERROR - Infinity polling: polling exited
2025-02-03 17 - TeleBot - ERROR - Break infinity polling
2025-02-03 17 - root - INFO - '–ü–µ—Ç—è'
2025-02-03 17 - root - INFO - '–î–∞ –ø–µ—Ç—è'
2025-02-03 17 - root - INFO - '—è —Å–∫–∞–∑–∞–ª –ø–µ—Ç—è—è—è—è—è—è—è—è—è—è'
2025-02-03 17 - TeleBot - ERROR - Infinity polling exception: '—Ñ—É'
2025-02-03 17 - TeleBot - ERROR - Exception traceback:
Traceback (most recent call last):
  File "C:\Users\–¢–∏–º–∞\PycharmProjects\TelegramBot\venv\Lib\site-packages\telebot\__init__.py", line 1110, in infinity_polling
    self.polling(non_stop=True, timeout=timeout, long_polling_timeout=long_polling_timeout,
    ~~~~~~~~~~~~^^^^^^^^^^^^^^^^^^^^^^^^^^^^^^^^^^^^^^^^^^^^^^^^^^^^^^^^^^^^^^^^^^^^^^^^^^^
                 logger_level=logger_level, allowed_updates=allowed_updates, restart_on_change=False,
                 ^^^^^^^^^^^^^^^^^^^^^^^^^^^^^^^^^^^^^^^^^^^^^^^^^^^^^^^^^^^^^^^^^^^^^^^^^^^^^^^^^^^^
                 *args, **kwargs)
                 ^^^^^^^^^^^^^^^^
  File "C:\Users\–¢–∏–º–∞\PycharmProjects\TelegramBot\venv\Lib\site-packages\telebot\__init__.py", line 1198, in polling
    self.__threaded_polling(non_stop=non_stop, interval=interval, timeout=timeout, long_polling_timeout=long_polling_timeout,
    ~~~~~~~~~~~~~~~~~~~~~~~^^^^^^^^^^^^^^^^^^^^^^^^^^^^^^^^^^^^^^^^^^^^^^^^^^^^^^^^^^^^^^^^^^^^^^^^^^^^^^^^^^^^^^^^^^^^^^^^^^
                            logger_level=logger_level, allowed_updates=allowed_updates)
                            ^^^^^^^^^^^^^^^^^^^^^^^^^^^^^^^^^^^^^^^^^^^^^^^^^^^^^^^^^^^
  File "C:\Users\–¢–∏–º–∞\PycharmProjects\TelegramBot\venv\Lib\site-packages\telebot\__init__.py", line 1273, in __threaded_polling
    raise e
  File "C:\Users\–¢–∏–º–∞\PycharmProjects\TelegramBot\venv\Lib\site-packages\telebot\__init__.py", line 1235, in __threaded_polling
    self.worker_pool.raise_exceptions()
    ~~~~~~~~~~~~~~~~~~~~~~~~~~~~~~~~~^^
  File "C:\Users\–¢–∏–º–∞\PycharmProjects\TelegramBot\venv\Lib\site-packages\telebot\util.py", line 150, in raise_exceptions
    raise self.exception_info
  File "C:\Users\–¢–∏–º–∞\PycharmProjects\TelegramBot\venv\Lib\site-packages\telebot\util.py", line 93, in run
    task(*args, **kwargs)
    ~~~~^^^^^^^^^^^^^^^^^
  File "C:\Users\–¢–∏–º–∞\PycharmProjects\TelegramBot\main.py", line 132, in set_settings
    reply_markup=create_keyboard(VALUES[msg.text]))
                                 ~~~~~~^^^^^^^^^^
KeyError: '—Ñ—É'

2025-02-03 17 - TeleBot - ERROR - Infinity polling: polling exited
2025-02-03 17 - TeleBot - ERROR - Break infinity polling
2025-02-03 17 - TeleBot - ERROR - Infinity polling: polling exited
2025-02-03 17 - TeleBot - ERROR - Break infinity polling
2025-02-03 18 - TeleBot - ERROR - Infinity polling: polling exited
2025-02-03 18 - TeleBot - ERROR - Break infinity polling
2025-02-03 18 - TeleBot - ERROR - Infinity polling: polling exited
2025-02-03 18 - TeleBot - ERROR - Break infinity polling
2025-02-03 18 - TeleBot - ERROR - Infinity polling: polling exited
2025-02-03 18 - TeleBot - ERROR - Break infinity polling
